Workbook

Sheet 填寫說明
B1: 個人職能盤點表
B3: 步驟 | C3: 工作表 | D3: 說明
B4: 1 | C4: 職能辭典 | D4: 確認或修改職能項目、定義與 L1–L5 行為描述，使其符合貴組織（黃底可編輯）。產品線職能（P06–P17）另以「適用產品」「適用職能別」限定對象。
B5: 2 | C5: 職務職能需求 | D5: 設定各職稱對每項職能的要求等級（1–5，0＝不適用）。
B6: 3 | C6: 員工名單 | D6: 填入受盤點人員基本資料；職稱請由下拉選單選擇。「負責產品」與「職能別」決定適用哪些產品線職能。
B7: 4 | C7: 個人職能盤點 | D7: 每位員工每項職能一列：輸入員工編號、選擇職能項目，填自評與主管評等級及佐證、發展計畫。姓名、部門、職稱、類別、要求等級、差距與狀態會自動帶出。
B8: 5 | C8: 個人彙總／職能彙總 | D8: 自動計算，不需填寫。可用於個人發展面談（IDP）與年度訓練需求分析。
B10: 圖例
C11: 黃底：需填寫或可修改的欄位
C12: 灰底灰字：範例資料（王小明），正式使用前請刪除
C13: 白底：公式自動計算，請勿修改
C14: 藍字：手動輸入的設定值（要求等級）
B16: 分級定義
B17: 等級 | C17: 獨立程度 | D17: 問題複雜度 | H17: 影響範圍 | K17: 參考對應
B18: 專家 | C18: 制定標準並指導他人 | D18: 新型、高風險、沒有前例的問題 | H18: 組織或客戶層級 | K18: 架構師、Partner，約 7 年以上
B19: 進階 | C19: 獨立完成，能依情境調整做法 | D19: 跨系統、需要判斷取捨的問題 | H19: 專案或團隊 | K19: 資深人員、顧問，約 3–7 年
B20: 基礎 | C20: 在指導下依既有流程完成 | D20: 常規、已有解法的問題 | H20: 個人任務 | K20: 初階人員，約 1–3 年經驗
B22: 等級定義
B23: L1 | C23: 在指導下能理解並執行基本要求
B24: L2 | C24: 能獨立執行一般性工作，偶需協助
B25: L3 | C25: 能獨立處理複雜狀況並確保成果品質
B26: L4 | C26: 能指導他人並優化做法，為單位內標竿
B27: L5 | C27: 能建立制度或方法論，影響全組織
B29: 達成狀態
B30: 超越 | C30: 主管評 > 要求等級
B31: 達標 | C31: 主管評 = 要求等級
B32: 待發展 | C32: 主管評 < 要求等級，建議列入個人發展計畫
B33: 待評核 | C33: 主管尚未評分
B34: 不適用 | C34: 該職稱不要求此職能（要求等級＝0）

Sheet 1.職能辭典
A1: 職能類別 | B1: 代碼 | C1: 職能項目 | D1: 職能定義 | E1: L1 基礎 | F1: L2 執行 | G1: L3 熟練 | H1: L4 精通 | I1: L5 專家 | J1: 適用產品 | K1: 適用職能別
A2: 核心職能 | B2: C01 | C2: 誠信正直 | D2: 遵守法規與公司規範，言行一致、信守承諾，維護組織信譽。 | E2: 在指導下能理解並執行基本要求 | F2: 能獨立執行一般性工作，偶需協助 | G2: 能獨立處理複雜狀況並確保成果品質 | H2: 能指導他人並優化做法，為單位內標竿 | I2: 能建立制度或方法論，影響全組織 | J2: 全部 | K2: 全部
A3: 核心職能 | B3: C02 | C3: 顧客導向 | D3: 了解內外部顧客需求，主動提供有價值的服務與解決方案。 | E3: 在指導下能理解並執行基本要求 | F3: 能獨立執行一般性工作，偶需協助 | G3: 能獨立處理複雜狀況並確保成果品質 | H3: 能指導他人並優化做法，為單位內標竿 | I3: 能建立制度或方法論，影響全組織 | J3: 全部 | K3: 全部
A4: 核心職能 | B4: C03 | C4: 團隊合作 | D4: 跨部門協作、分享資訊與資源，共同達成團隊目標。 | E4: 在指導下能理解並執行基本要求 | F4: 能獨立執行一般性工作，偶需協助 | G4: 能獨立處理複雜狀況並確保成果品質 | H4: 能指導他人並優化做法，為單位內標竿 | I4: 能建立制度或方法論，影響全組織 | J4: 全部 | K4: 全部
A5: 核心職能 | B5: C04 | C5: 持續學習 | D5: 主動學習新知與技能，並將所學應用於工作改善。 | E5: 在指導下能理解並執行基本要求 | F5: 能獨立執行一般性工作，偶需協助 | G5: 能獨立處理複雜狀況並確保成果品質 | H5: 能指導他人並優化做法，為單位內標竿 | I5: 能建立制度或方法論，影響全組織 | J5: 全部 | K5: 全部
A6: 核心職能 | B6: C05 | C6: 創新改善 | D6: 挑戰現況、提出新做法，持續優化工作流程與成果。 | E6: 在指導下能理解並執行基本要求 | F6: 能獨立執行一般性工作，偶需協助 | G6: 能獨立處理複雜狀況並確保成果品質 | H6: 能指導他人並優化做法，為單位內標竿 | I6: 能建立制度或方法論，影響全組織 | J6: 全部 | K6: 全部
A7: 管理職能 | B7: M01 | C7: 領導統御 | D7: 設定方向、激勵部屬，帶領團隊達成組織目標。 | E7: 在指導下能理解並執行基本要求 | F7: 能獨立執行一般性工作，偶需協助 | G7: 能獨立處理複雜狀況並確保成果品質 | H7: 能指導他人並優化做法，為單位內標竿 | I7: 能建立制度或方法論，影響全組織 | J7: 全部 | K7: 全部
A8: 管理職能 | B8: M02 | C8: 決策判斷 | D8: 蒐集與分析資訊，在時限內做出合宜決策並承擔責任。 | E8: 在指導下能理解並執行基本要求 | F8: 能獨立執行一般性工作，偶需協助 | G8: 能獨立處理複雜狀況並確保成果品質 | H8: 能指導他人並優化做法，為單位內標竿 | I8: 能建立制度或方法論，影響全組織 | J8: 全部 | K8: 全部
A9: 管理職能 | B9: M03 | C9: 目標管理 | D9: 將組織目標展開為可衡量的計畫，追蹤進度並適時調整。 | E9: 在指導下能理解並執行基本要求 | F9: 能獨立執行一般性工作，偶需協助 | G9: 能獨立處理複雜狀況並確保成果品質 | H9: 能指導他人並優化做法，為單位內標竿 | I9: 能建立制度或方法論，影響全組織 | J9: 全部 | K9: 全部
A10: 管理職能 | B10: M04 | C10: 人才培育 | D10: 識別部屬發展需求，透過指導、授權與回饋提升其能力。 | E10: 在指導下能理解並執行基本要求 | F10: 能獨立執行一般性工作，偶需協助 | G10: 能獨立處理複雜狀況並確保成果品質 | H10: 能指導他人並優化做法，為單位內標竿 | I10: 能建立制度或方法論，影響全組織 | J10: 全部 | K10: 全部
A11: 管理職能 | B11: M05 | C11: 溝通協調 | D11: 清楚傳達訊息、整合不同意見，化解衝突並促成共識。 | E11: 在指導下能理解並執行基本要求 | F11: 能獨立執行一般性工作，偶需協助 | G11: 能獨立處理複雜狀況並確保成果品質 | H11: 能指導他人並優化做法，為單位內標竿 | I11: 能建立制度或方法論，影響全組織 | J11: 全部 | K11: 全部
A12: 專業職能 | B12: P01 | C12: 專業知識 | D12: 具備擔任職務所需的領域知識、法規與標準。 | E12: 在指導下能理解並執行基本要求 | F12: 能獨立執行一般性工作，偶需協助 | G12: 能獨立處理複雜狀況並確保成果品質 | H12: 能指導他人並優化做法，為單位內標竿 | I12: 能建立制度或方法論，影響全組織 | J12: 全部 | K12: 全部
... A28: 專業職能 | B28: P17 | C28: 儲值爭議與帳務協查 | D28: 處理儲值未到帳、退款、盜刷等爭議，並與金流商及財務部協同查核。 | E28: 能依流程受理儲值問題並轉交相關單位 | F28: 能獨立查核一般儲值紀錄並回覆玩家 | G28: 能處理退款、盜刷等複雜爭議並與金流商協調 | H28: 能優化協查流程並指導他人 | I28: 能建立儲值爭議處理制度與風險控管機制 | J28: 全部 | K28: 客服、財務

Sheet 2.職務職能需求
A1: 職能項目 | B1: 經理/副理 | C1: 部門主管 | D1: (專家) | E1: (進階) | F1: (基礎)
A2: ='1.職能辭典'!C2 | B2: 4 | C2: 4 | D2: 3 | E2: 3 | F2: 3
A3: ='1.職能辭典'!C3 | B3: 4 | C3: 3 | D3: 3 | E3: 3 | F3: 2
A4: ='1.職能辭典'!C4 | B4: 4 | C4: 3 | D4: 3 | E4: 3 | F4: 3
A5: ='1.職能辭典'!C5 | B5: 4 | C5: 3 | D5: 3 | E5: 3 | F5: 2
A6: ='1.職能辭典'!C6 | B6: 4 | C6: 3 | D6: 3 | E6: 2 | F6: 2
A7: ='1.職能辭典'!C7 | B7: 4 | C7: 3 | D7: 0 | E7: 0 | F7: 0
A8: ='1.職能辭典'!C8 | B8: 4 | C8: 3 | D8: 2 | E8: 0 | F8: 0
A9: ='1.職能辭典'!C9 | B9: 4 | C9: 3 | D9: 2 | E9: 0 | F9: 0
A10: ='1.職能辭典'!C10 | B10: 4 | C10: 3 | D10: 2 | E10: 0 | F10: 0
A11: ='1.職能辭典'!C11 | B11: 4 | C11: 3 | D11: 3 | E11: 2 | F11: 2
A12: ='1.職能辭典'!C12 | B12: 4 | C12: 4 | D12: 4 | E12: 3 | F12: 2
A13: ='1.職能辭典'!C13 | B13: 3 | C13: 3 | D13: 4 | E13: 3 | F13: 2
... A16: ='1.職能辭典'!C16 | B16: 3 | C16: 3 | D16: 3 | E16: 2 | F16: 2
A17: 活動營運企劃 | B17: 3 | C17: 4 | D17: 4 | E17: 3 | F17: 2
A18: 數據分析與營運指標 | B18: 3 | C18: 4 | D18: 4 | E18: 3 | F18: 2
A19: 推廣投放與社群行銷 | B19: 3 | C19: 4 | D19: 4 | E19: 3 | F19: 2
A20: 牌局玩法與機率設計 | B20: 3 | C20: 4 | D20: 4 | E20: 3 | F20: 2
A21: 棋牌合規與風控 | B21: 3 | C21: 4 | D21: 4 | E21: 3 | F21: 2
A22: 養成數值與經濟系統設計 | B22: 3 | C22: 4 | D22: 4 | E22: 3 | F22: 2
A23: 寵物內容與社群經營 | B23: 3 | C23: 4 | D23: 4 | E23: 3 | F23: 2
A24: 遊戲美術製作與風格適配 | B24: 3 | C24: 4 | D24: 4 | E24: 3 | F24: 2
A25: 遊戲開發與金流串接 | B25: 3 | C25: 4 | D25: 4 | E25: 3 | F25: 2
A26: 遊戲測試與版本品質把關 | B26: 3 | C26: 4 | D26: 4 | E26: 3 | F26: 2
A27: 玩家客服與客訴處理 | B27: 3 | C27: 4 | D27: 4 | E27: 3 | F27: 2
A28: 儲值爭議與帳務協查 | B28: 3 | C28: 4 | D28: 4 | E28: 3 | F28: 2
A30: 說明：數值為該職稱對各職能的「要求等級」（1–5），0＝不適用。職稱可增刪欄位（需同步調整員工名單的職稱下拉選單）。
A31: 產品線職能（P06–P17）另依「1.職能辭典」的適用產品與適用職能別判斷；不適用者在個人職能盤點自動顯示「不適用」。

Sheet 3.員工名單
A1: 員工編號 | B1: 姓名 | C1: 部門 | D1: 職稱 | E1: 到職日 | F1: 直屬主管 | G1: 盤點期間 | H1: 負責產品 | I1: 職能別 | J1: 管理職能 (Management Track) | K1: 技術與專業職能 (Technical Track)
A2: A001 | B2: 吳怡慶 | C2: 總經理室 | D2: 經理/副理 | E2: 43221 | F2: - | H2: 公司共用 | I2: 經營 | J2: 企業整體戰略決策與發展願景制定 (M01/M02)； 年度資本預算 (CAPEX/OPEX) 與經營目標考核 (M03)； 最高營運裁決、法律委任與董事會治理； 重大風險控管與最終簽核核決權 | K2: 棋牌與互聯網平台商業模式設計； 股權與組織治理架構規劃； 跨領域策略投資與商務生態構建； 高階經營分析與績效指標 (KPI) 體系
A3: B026 | B3: 廖倫豪 | C3: 副總經理室 | D3: 經理/副理 | E3: 45786 | F3: 吳怡慶 | H3: 兩款共用 | I3: 技術 | J3: 跨部門研發與營運資源統籌排程 (M01/M03)； 管理部 (人資/財務) 簽核案件事前審核 (副總經理審簽)； 企業內控制度、SoD 牽制與四眼原則主導 (M02)； 研發部跨組績效考評與高階技術導師 (M04/M05) | K3: 企業架構 (EA)、雲原生多雲容器 (GKE/K8s) 與 FinOps； 高併發微服務 API-first、CSPRNG 隨機算法公正性認證； 大數據中台、即時 BI 看板與 AI 工作流落地； ISO 27001 / ISO 42001 (AIMS) 主任稽核員資安治理
A4: A002 | B4: 陳建州 | C4: 管理部／人資總務組 | D4: 部門主管 | E4: 43221 | F4: 吳怡慶 | H4: 鬥陣歡樂城（代理人） | I4: 企劃、營運、管理 | J4: 人資與總務組整體運作指揮與工作督導 (M01/M03)； 勞資爭議預防、薪酬福利與績效考核制度管理 (M02)； 全公司行政採購合約審查與辦公環境治理 (M02)； 副總經理審簽案件事前審核與行政呈核 (M05) | K4: 勞基法規、勞健保申報與人力資源法遵； 固定資產全生命週期管制與盤點稽核機制； 行政採購詢比議價標準規範與供應商評鑑； 鬥陣歡樂城營運支援與行政資源即時調配
A5: A003 | B5: 王慈汶 | C5: 財務部 | D5: 部門主管 | E5: 43262 | F5: 吳怡慶 | H5: 公司共用 | I5: 財務 | J5: 財務部全面工作領導、預算編制與資金調度 (M01/M03)；內部財務牽制 (SoD)、防弊四眼審核與放行 (M02)；副總經理審簽案件之財務憑證完整性審查 (M05)；部門同仁傳票複核、稅務申報與專業輔導 (M04) | K5: 企業會計準則 (EAS/IFRS 15) 收入認列 (房卡合約負債)； 財務三表 (資產負債表/損益表/現金流量表) 編製與分析； 銀行融資對接、資金池調度與外匯風險控管； 營業稅、營所稅與各類所得扣繳申報實務
A6: A011 | B6: 魏淑禎 | C6: 技術部／美術組 | D6: 部門主管 | E6: 43739 | F6: 廖倫豪 | H6: 兩款共用 | I6: 美術 | J6: 美術組專案排程規劃、派工與資源負載調配 (M03)； 外包美術團隊詢比議價審核與嚴格驗收管制 (M02)； 美術團隊風格適配指導與人才梯度培育 (M04)； 美術組與企劃、技術組之需求規格對齊 (M05) | K6: 台味茶館、客棧紅木桌、宣紙印章國風視覺標準定義； 遊戲 UI/UX 系統規範手冊 (Design System) 制定； 原創角色形象塑造 (如熊貓大俠「潘達」) 與立繪； 外包交付分層源檔 (PSD/FBX/Spine) 像素級驗收
A7: A012 | B7: 潘羿彰 | C7: 技術部／美術組 | D7: (進階) | E7: 43739 | F7: 魏淑禎 | H7: 兩款共用 | I7: 主管代理人 | J7: 資深美術模組化資產交接與管理； 動效與特效資源交付進度把關； 協助初階美術進行動畫分層與性能規範校正 | K7: Spine 2D 骨骼動畫綁定、動態權重與骨架優化； 棋牌與寵物遊戲視覺特效 (VFX) 粒子系統設計； 角色動態表情包與打牌動作流暢度調校； 高解析度角色立繪與戰鬥特效製作
A8: A022 | B8: 趙柏凱 | C8: 技術部／開發組 | D8: 部門主管 | E8: 43935 | F8: 廖倫豪 | H8: 兩款共用 | I8: 技術 | J8: 技術組工程師任務派工與 Sprint 週期進度管理 (M03)； GitLab 代碼審查 (Code Review) 制度建立與落地 (M02)； 初中階工程師技術培訓與梯隊培育 (M04)； 技術組與企劃、測試、維運之跨組協調溝通 (M05) | K8: 棋牌遊戲核心引擎架構與狀態機 (FSM) 設計； WebSocket 高併發通訊協定與分散式長連線維護； 後端架構 (C++ / Go / Node.js) 與高效能運算； 資料庫連線池調優、防外掛數據封包加密
A9: A033 | B9: 曾翊庭 | C9: 企劃暨營運推廣 | D9: (進階) | E9: 44244 | F9: 張哲豪 | H9: 寵物遊戲（代理人 ． 兼任測試組） | I9: 代理人 | J9: 企劃部正職；寵物遊戲營運活動上線排程進度追蹤；兼任研發部測試組之交叉驗收協同；社群玩家熱點需求彙總與企劃提案 | K9: 寵物養成數值配置與關卡數值調整；日常營運活動參數上架與驗證測試；兼任跨平台功能驗收與使用者體驗 (UX) 測試；營運數據日報產出與異常數值波動排查
A10: A049 | B10: 凃睿修 | C10: 技術部／測試組 | D10: 部門主管 | E10: 44629 | F10: 廖倫豪 | H10: 兩款共用 | I10: 測試 | J10: 測試組測試計畫 (Test Plan) 擬定與時程規劃 (M03)； 發版品質守門人 (Quality Gate)，Blocker 歸零審定 (M02)； 缺陷管理流程 (Bug Lifecycle) 規範與落實； 跨組對齊技術、企劃之問題重現與驗收標準 (M05) | K10: 棋牌核心麻將算番、碰槓胡牌局邏輯邊界測試； 跨平台 (iOS/Android/模擬器) 相容性與壓力負載測試； 弱網模擬 (Packet Loss/Delay) 與斷線重連健全性驗證； Jira/TestRail 測試用例矩陣編寫與自動化腳本應用
A11: A051 | B11: 林秉韶 | C11: 技術部／開發組 | D11: (進階) | E11: 44648 | F11: 趙柏凱 | H11: 兩款共用 | I11: 主管代理人 | J11: 前端模組化交付時程掌控與自主管理； 跨平台客戶端發版檢查清單 (Checklist) 落實； 協助初階工程師釐清前端渲染與邏輯異常 | K11: Cocos Creator / Unity 前端跨平台開發； iOS / Android / WebGL 多端渲染與適配調優； 客戶端熱更新 (Hot Update) 機制與資源加載優化； WebSocket 前端重連、斷線續玩與即時對弈平滑化
A12: A057 | B12: 陳俞任 | C12: 技術部／美術組 | D12: (進階) | E12: 44684 | F12: 魏淑禎 | H12: 兩款共用 | I12: 美術 | J12: 介面 UI 模組規範化管理與版本同步； 美術資源命名規範檢查與產出追蹤； 與前端工程師對齊 UI 標註與切圖資產 | K12: 遊戲主介面、彈窗、選單 UI/UX 全套視覺設計； 多螢幕長寬比 (16:9 / 20:9 / 平板) 介面適配切圖； 棋牌牌桌、卡牌牌面、籌碼等元件高精度刻畫； 向量圖標 (Icon) 與動態按鈕回饋設計
A13: A060 | B13: 張哲豪 | C13: 企劃暨營運推廣 | D13: 部門主管 | E13: 44805 | F13: 廖倫豪 | H13: 寵物遊戲 | I13: 企劃、營運 | J13: 寵物養成遊戲產品路線圖 (Roadmap) 規劃與掌控 (M01/M03)； 寵物產品線跨職能 (研發/美術/營運) 敏捷協調 (M05)； 活動檔期排程審定與營收預測目標達成管控 (M02)； 企劃部人才培育與遊戲數值平衡性審核 (M04) | K13: 寵物養成核心玩法循環 (Core Loop) 設計； 遊戲經濟系統平衡與數值模型設計 (Excel VBA/Python)； 營運付費活動策劃與留存指標 (DAU/ARPPU/LTV) 分析； 企劃需求規格書 (GDD) 與功能流程圖撰寫
... A26: B030 | B26: 蕭智瑜 | C26: 技術部／測試組 | D26: (基礎) | E26: 46307 | F26: 凃睿修 | H26: 兩款共用 | I26: 主管代理人 | J26: 測試執行進度日報提交與缺陷回報； 測試用例 (Test Cases) 覆蓋率自主確認； 與研發工程師進行缺陷重現步驟溝通 | K26: 多端客戶端黑箱功能測試與 UI 走查； 各型號實機回歸測試 (Regression Testing)； 遊戲充值、房卡扣減流程驗證與數值檢查； 詳細 Bug 報告撰寫 (重現步驟、Log 擷取與截圖)

Sheet 4.個人職能盤點
A1: 員工編號 | B1: 姓名 | C1: 部門 | D1: 職稱 | E1: 職能類別 | F1: 職能項目 | G1: 要求等級 | H1: 自評等級 | I1: 主管評等級 | J1: 差距 (主管評−要求) | K1: 達成狀態 | L1: 具體行為事例／佐證 | M1: 發展建議／行動計畫 | N1: 預計完成日
B2: {=IF(A2="","",IFERROR(INDEX('3.員工名單'!$B:$B,MATCH(A2,'3.員工名單'!$A:$A,0)),"查無此員工"))} | C2: {=IF(A2="","",IFERROR(INDEX('3.員工名單'!$C:$C,MATCH(A2,'3.員工名單'!$A:$A,0)),""))} | D2: {=IF(A2="","",IFERROR(INDEX('3.員工名單'!$D:$D,MATCH(A2,'3.員工名單'!$A:$A,0)),""))} | E2: {=IF(F2="","",IFERROR(INDEX('1.職能辭典'!$A:$A,MATCH(F2,'1.職能辭典'!$C:$C,0)),""))} | G2: {=IF(OR(D2="",F2=""),"",IFERROR(IF(AND(OR(INDEX('1.職能辭典'!$J:$J,MATCH(F2,'1.職能辭典'!$C:$C,0))="全部",INDEX('3.員工名單'!$H:$H,MATCH(A2,'3.員工名單'!$A:$A,0))="兩款共用",INDEX('3.員工名單'!$H:$H,MATCH(A2,'3.員工名單'!$A:$A,0))=INDEX('1.職能辭典'!$J:$J,MATCH(F2,'1.職能辭典'!$C:$C,0))),OR(INDEX('1.職能辭典'!$K:$K,MATCH(F2,'1.職能辭典'!$C:$C,0))="全部",SUMPRODUCT(ISNUMBER(SEARCH({"經營","管理","財務","企劃","營運","技術","數據","美術","測試","客服"},INDEX('3.員工名單'!$I:$I,MATCH(A2,'3.員工名單'!$A:$A,0))))*ISNUMBER(SEARCH({"經營","管理","財務","企劃","營運","技術","數據","美術","測試","客服"},INDEX('1.職能辭典'!$K:$K,MATCH(F2,'1.職能辭典'!$C:$C,0)))))>0)),INDEX('2.職務職能需求'!$B$2:$F$28,MATCH(F2,'2.職務職能需求'!$A$2:$A$28,0),MATCH(D2,'2.職務職能需求'!$B$1:$F$1,0)),0),""))} | J2: =IF(OR(G2="",I2="",G2=0),"",I2-G2) | K2: =IF(G2="","",IF(G2=0,"不適用",IF(I2="","待評核",IF(I2>=G2,IF(I2>G2,"超越","達標"),"待發展"))))
B3: {=IF(A3="","",IFERROR(INDEX('3.員工名單'!$B:$B,MATCH(A3,'3.員工名單'!$A:$A,0)),"查無此員工"))} | C3: {=IF(A3="","",IFERROR(INDEX('3.員工名單'!$C:$C,MATCH(A3,'3.員工名單'!$A:$A,0)),""))} | D3: {=IF(A3="","",IFERROR(INDEX('3.員工名單'!$D:$D,MATCH(A3,'3.員工名單'!$A:$A,0)),""))} | E3: {=IF(F3="","",IFERROR(INDEX('1.職能辭典'!$A:$A,MATCH(F3,'1.職能辭典'!$C:$C,0)),""))} | G3: {=IF(OR(D3="",F3=""),"",IFERROR(IF(AND(OR(INDEX('1.職能辭典'!$J:$J,MATCH(F3,'1.職能辭典'!$C:$C,0))="全部",INDEX('3.員工名單'!$H:$H,MATCH(A3,'3.員工名單'!$A:$A,0))="兩款共用",INDEX('3.員工名單'!$H:$H,MATCH(A3,'3.員工名單'!$A:$A,0))=INDEX('1.職能辭典'!$J:$J,MATCH(F3,'1.職能辭典'!$C:$C,0))),OR(INDEX('1.職能辭典'!$K:$K,MATCH(F3,'1.職能辭典'!$C:$C,0))="全部",SUMPRODUCT(ISNUMBER(SEARCH({"經營","管理","財務","企劃","營運","技術","數據","美術","測試","客服"},INDEX('3.員工名單'!$I:$I,MATCH(A3,'3.員工名單'!$A:$A,0))))*ISNUMBER(SEARCH({"經營","管理","財務","企劃","營運","技術","數據","美術","測試","客服"},INDEX('1.職能辭典'!$K:$K,MATCH(F3,'1.職能辭典'!$C:$C,0)))))>0)),INDEX('2.職務職能需求'!$B$2:$F$28,MATCH(F3,'2.職務職能需求'!$A$2:$A$28,0),MATCH(D3,'2.職務職能需求'!$B$1:$F$1,0)),0),""))} | J3: =IF(OR(G3="",I3="",G3=0),"",I3-G3) | K3: =IF(G3="","",IF(G3=0,"不適用",IF(I3="","待評核",IF(I3>=G3,IF(I3>G3,"超越","達標"),"待發展"))))
B4: {=IF(A4="","",IFERROR(INDEX('3.員工名單'!$B:$B,MATCH(A4,'3.員工名單'!$A:$A,0)),"查無此員工"))} | C4: {=IF(A4="","",IFERROR(INDEX('3.員工名單'!$C:$C,MATCH(A4,'3.員工名單'!$A:$A,0)),""))} | D4: {=IF(A4="","",IFERROR(INDEX('3.員工名單'!$D:$D,MATCH(A4,'3.員工名單'!$A:$A,0)),""))} | E4: {=IF(F4="","",IFERROR(INDEX('1.職能辭典'!$A:$A,MATCH(F4,'1.職能辭典'!$C:$C,0)),""))} | G4: {=IF(OR(D4="",F4=""),"",IFERROR(IF(AND(OR(INDEX('1.職能辭典'!$J:$J,MATCH(F4,'1.職能辭典'!$C:$C,0))="全部",INDEX('3.員工名單'!$H:$H,MATCH(A4,'3.員工名單'!$A:$A,0))="兩款共用",INDEX('3.員工名單'!$H:$H,MATCH(A4,'3.員工名單'!$A:$A,0))=INDEX('1.職能辭典'!$J:$J,MATCH(F4,'1.職能辭典'!$C:$C,0))),OR(INDEX('1.職能辭典'!$K:$K,MATCH(F4,'1.職能辭典'!$C:$C,0))="全部",SUMPRODUCT(ISNUMBER(SEARCH({"經營","管理","財務","企劃","營運","技術","數據","美術","測試","客服"},INDEX('3.員工名單'!$I:$I,MATCH(A4,'3.員工名單'!$A:$A,0))))*ISNUMBER(SEARCH({"經營","管理","財務","企劃","營運","技術","數據","美術","測試","客服"},INDEX('1.職能辭典'!$K:$K,MATCH(F4,'1.職能辭典'!$C:$C,0)))))>0)),INDEX('2.職務職能需求'!$B$2:$F$28,MATCH(F4,'2.職務職能需求'!$A$2:$A$28,0),MATCH(D4,'2.職務職能需求'!$B$1:$F$1,0)),0),""))} | J4: =IF(OR(G4="",I4="",G4=0),"",I4-G4) | K4: =IF(G4="","",IF(G4=0,"不適用",IF(I4="","待評核",IF(I4>=G4,IF(I4>G4,"超越","達標"),"待發展"))))
B5: {=IF(A5="","",IFERROR(INDEX('3.員工名單'!$B:$B,MATCH(A5,'3.員工名單'!$A:$A,0)),"查無此員工"))} | C5: {=IF(A5="","",IFERROR(INDEX('3.員工名單'!$C:$C,MATCH(A5,'3.員工名單'!$A:$A,0)),""))} | D5: {=IF(A5="","",IFERROR(INDEX('3.員工名單'!$D:$D,MATCH(A5,'3.員工名單'!$A:$A,0)),""))} | E5: {=IF(F5="","",IFERROR(INDEX('1.職能辭典'!$A:$A,MATCH(F5,'1.職能辭典'!$C:$C,0)),""))} | G5: {=IF(OR(D5="",F5=""),"",IFERROR(IF(AND(OR(INDEX('1.職能辭典'!$J:$J,MATCH(F5,'1.職能辭典'!$C:$C,0))="全部",INDEX('3.員工名單'!$H:$H,MATCH(A5,'3.員工名單'!$A:$A,0))="兩款共用",INDEX('3.員工名單'!$H:$H,MATCH(A5,'3.員工名單'!$A:$A,0))=INDEX('1.職能辭典'!$J:$J,MATCH(F5,'1.職能辭典'!$C:$C,0))),OR(INDEX('1.職能辭典'!$K:$K,MATCH(F5,'1.職能辭典'!$C:$C,0))="全部",SUMPRODUCT(ISNUMBER(SEARCH({"經營","管理","財務","企劃","營運","技術","數據","美術","測試","客服"},INDEX('3.員工名單'!$I:$I,MATCH(A5,'3.員工名單'!$A:$A,0))))*ISNUMBER(SEARCH({"經營","管理","財務","企劃","營運","技術","數據","美術","測試","客服"},INDEX('1.職能辭典'!$K:$K,MATCH(F5,'1.職能辭典'!$C:$C,0)))))>0)),INDEX('2.職務職能需求'!$B$2:$F$28,MATCH(F5,'2.職務職能需求'!$A$2:$A$28,0),MATCH(D5,'2.職務職能需求'!$B$1:$F$1,0)),0),""))} | J5: =IF(OR(G5="",I5="",G5=0),"",I5-G5) | K5: =IF(G5="","",IF(G5=0,"不適用",IF(I5="","待評核",IF(I5>=G5,IF(I5>G5,"超越","達標"),"待發展"))))
B6: {=IF(A6="","",IFERROR(INDEX('3.員工名單'!$B:$B,MATCH(A6,'3.員工名單'!$A:$A,0)),"查無此員工"))} | C6: {=IF(A6="","",IFERROR(INDEX('3.員工名單'!$C:$C,MATCH(A6,'3.員工名單'!$A:$A,0)),""))} | D6: {=IF(A6="","",IFERROR(INDEX('3.員工名單'!$D:$D,MATCH(A6,'3.員工名單'!$A:$A,0)),""))} | E6: {=IF(F6="","",IFERROR(INDEX('1.職能辭典'!$A:$A,MATCH(F6,'1.職能辭典'!$C:$C,0)),""))} | G6: {=IF(OR(D6="",F6=""),"",IFERROR(IF(AND(OR(INDEX('1.職能辭典'!$J:$J,MATCH(F6,'1.職能辭典'!$C:$C,0))="全部",INDEX('3.員工名單'!$H:$H,MATCH(A6,'3.員工名單'!$A:$A,0))="兩款共用",INDEX('3.員工名單'!$H:$H,MATCH(A6,'3.員工名單'!$A:$A,0))=INDEX('1.職能辭典'!$J:$J,MATCH(F6,'1.職能辭典'!$C:$C,0))),OR(INDEX('1.職能辭典'!$K:$K,MATCH(F6,'1.職能辭典'!$C:$C,0))="全部",SUMPRODUCT(ISNUMBER(SEARCH({"經營","管理","財務","企劃","營運","技術","數據","美術","測試","客服"},INDEX('3.員工名單'!$I:$I,MATCH(A6,'3.員工名單'!$A:$A,0))))*ISNUMBER(SEARCH({"經營","管理","財務","企劃","營運","技術","數據","美術","測試","客服"},INDEX('1.職能辭典'!$K:$K,MATCH(F6,'1.職能辭典'!$C:$C,0)))))>0)),INDEX('2.職務職能需求'!$B$2:$F$28,MATCH(F6,'2.職務職能需求'!$A$2:$A$28,0),MATCH(D6,'2.職務職能需求'!$B$1:$F$1,0)),0),""))} | J6: =IF(OR(G6="",I6="",G6=0),"",I6-G6) | K6: =IF(G6="","",IF(G6=0,"不適用",IF(I6="","待評核",IF(I6>=G6,IF(I6>G6,"超越","達標"),"待發展"))))
B7: {=IF(A7="","",IFERROR(INDEX('3.員工名單'!$B:$B,MATCH(A7,'3.員工名單'!$A:$A,0)),"查無此員工"))} | C7: {=IF(A7="","",IFERROR(INDEX('3.員工名單'!$C:$C,MATCH(A7,'3.員工名單'!$A:$A,0)),""))} | D7: {=IF(A7="","",IFERROR(INDEX('3.員工名單'!$D:$D,MATCH(A7,'3.員工名單'!$A:$A,0)),""))} | E7: {=IF(F7="","",IFERROR(INDEX('1.職能辭典'!$A:$A,MATCH(F7,'1.職能辭典'!$C:$C,0)),""))} | G7: {=IF(OR(D7="",F7=""),"",IFERROR(IF(AND(OR(INDEX('1.職能辭典'!$J:$J,MATCH(F7,'1.職能辭典'!$C:$C,0))="全部",INDEX('3.員工名單'!$H:$H,MATCH(A7,'3.員工名單'!$A:$A,0))="兩款共用",INDEX('3.員工名單'!$H:$H,MATCH(A7,'3.員工名單'!$A:$A,0))=INDEX('1.職能辭典'!$J:$J,MATCH(F7,'1.職能辭典'!$C:$C,0))),OR(INDEX('1.職能辭典'!$K:$K,MATCH(F7,'1.職能辭典'!$C:$C,0))="全部",SUMPRODUCT(ISNUMBER(SEARCH({"經營","管理","財務","企劃","營運","技術","數據","美術","測試","客服"},INDEX('3.員工名單'!$I:$I,MATCH(A7,'3.員工名單'!$A:$A,0))))*ISNUMBER(SEARCH({"經營","管理","財務","企劃","營運","技術","數據","美術","測試","客服"},INDEX('1.職能辭典'!$K:$K,MATCH(F7,'1.職能辭典'!$C:$C,0)))))>0)),INDEX('2.職務職能需求'!$B$2:$F$28,MATCH(F7,'2.職務職能需求'!$A$2:$A$28,0),MATCH(D7,'2.職務職能需求'!$B$1:$F$1,0)),0),""))} | J7: =IF(OR(G7="",I7="",G7=0),"",I7-G7) | K7: =IF(G7="","",IF(G7=0,"不適用",IF(I7="","待評核",IF(I7>=G7,IF(I7>G7,"超越","達標"),"待發展"))))
B8: {=IF(A8="","",IFERROR(INDEX('3.員工名單'!$B:$B,MATCH(A8,'3.員工名單'!$A:$A,0)),"查無此員工"))} | C8: {=IF(A8="","",IFERROR(INDEX('3.員工名單'!$C:$C,MATCH(A8,'3.員工名單'!$A:$A,0)),""))} | D8: {=IF(A8="","",IFERROR(INDEX('3.員工名單'!$D:$D,MATCH(A8,'3.員工名單'!$A:$A,0)),""))} | E8: {=IF(F8="","",IFERROR(INDEX('1.職能辭典'!$A:$A,MATCH(F8,'1.職能辭典'!$C:$C,0)),""))} | G8: {=IF(OR(D8="",F8=""),"",IFERROR(IF(AND(OR(INDEX('1.職能辭典'!$J:$J,MATCH(F8,'1.職能辭典'!$C:$C,0))="全部",INDEX('3.員工名單'!$H:$H,MATCH(A8,'3.員工名單'!$A:$A,0))="兩款共用",INDEX('3.員工名單'!$H:$H,MATCH(A8,'3.員工名單'!$A:$A,0))=INDEX('1.職能辭典'!$J:$J,MATCH(F8,'1.職能辭典'!$C:$C,0))),OR(INDEX('1.職能辭典'!$K:$K,MATCH(F8,'1.職能辭典'!$C:$C,0))="全部",SUMPRODUCT(ISNUMBER(SEARCH({"經營","管理","財務","企劃","營運","技術","數據","美術","測試","客服"},INDEX('3.員工名單'!$I:$I,MATCH(A8,'3.員工名單'!$A:$A,0))))*ISNUMBER(SEARCH({"經營","管理","財務","企劃","營運","技術","數據","美術","測試","客服"},INDEX('1.職能辭典'!$K:$K,MATCH(F8,'1.職能辭典'!$C:$C,0)))))>0)),INDEX('2.職務職能需求'!$B$2:$F$28,MATCH(F8,'2.職務職能需求'!$A$2:$A$28,0),MATCH(D8,'2.職務職能需求'!$B$1:$F$1,0)),0),""))} | J8: =IF(OR(G8="",I8="",G8=0),"",I8-G8) | K8: =IF(G8="","",IF(G8=0,"不適用",IF(I8="","待評核",IF(I8>=G8,IF(I8>G8,"超越","達標"),"待發展"))))
B9: {=IF(A9="","",IFERROR(INDEX('3.員工名單'!$B:$B,MATCH(A9,'3.員工名單'!$A:$A,0)),"查無此員工"))} | C9: {=IF(A9="","",IFERROR(INDEX('3.員工名單'!$C:$C,MATCH(A9,'3.員工名單'!$A:$A,0)),""))} | D9: {=IF(A9="","",IFERROR(INDEX('3.員工名單'!$D:$D,MATCH(A9,'3.員工名單'!$A:$A,0)),""))} | E9: {=IF(F9="","",IFERROR(INDEX('1.職能辭典'!$A:$A,MATCH(F9,'1.職能辭典'!$C:$C,0)),""))} | G9: {=IF(OR(D9="",F9=""),"",IFERROR(IF(AND(OR(INDEX('1.職能辭典'!$J:$J,MATCH(F9,'1.職能辭典'!$C:$C,0))="全部",INDEX('3.員工名單'!$H:$H,MATCH(A9,'3.員工名單'!$A:$A,0))="兩款共用",INDEX('3.員工名單'!$H:$H,MATCH(A9,'3.員工名單'!$A:$A,0))=INDEX('1.職能辭典'!$J:$J,MATCH(F9,'1.職能辭典'!$C:$C,0))),OR(INDEX('1.職能辭典'!$K:$K,MATCH(F9,'1.職能辭典'!$C:$C,0))="全部",SUMPRODUCT(ISNUMBER(SEARCH({"經營","管理","財務","企劃","營運","技術","數據","美術","測試","客服"},INDEX('3.員工名單'!$I:$I,MATCH(A9,'3.員工名單'!$A:$A,0))))*ISNUMBER(SEARCH({"經營","管理","財務","企劃","營運","技術","數據","美術","測試","客服"},INDEX('1.職能辭典'!$K:$K,MATCH(F9,'1.職能辭典'!$C:$C,0)))))>0)),INDEX('2.職務職能需求'!$B$2:$F$28,MATCH(F9,'2.職務職能需求'!$A$2:$A$28,0),MATCH(D9,'2.職務職能需求'!$B$1:$F$1,0)),0),""))} | J9: =IF(OR(G9="",I9="",G9=0),"",I9-G9) | K9: =IF(G9="","",IF(G9=0,"不適用",IF(I9="","待評核",IF(I9>=G9,IF(I9>G9,"超越","達標"),"待發展"))))
B10: {=IF(A10="","",IFERROR(INDEX('3.員工名單'!$B:$B,MATCH(A10,'3.員工名單'!$A:$A,0)),"查無此員工"))} | C10: {=IF(A10="","",IFERROR(INDEX('3.員工名單'!$C:$C,MATCH(A10,'3.員工名單'!$A:$A,0)),""))} | D10: {=IF(A10="","",IFERROR(INDEX('3.員工名單'!$D:$D,MATCH(A10,'3.員工名單'!$A:$A,0)),""))} | E10: {=IF(F10="","",IFERROR(INDEX('1.職能辭典'!$A:$A,MATCH(F10,'1.職能辭典'!$C:$C,0)),""))} | G10: {=IF(OR(D10="",F10=""),"",IFERROR(IF(AND(OR(INDEX('1.職能辭典'!$J:$J,MATCH(F10,'1.職能辭典'!$C:$C,0))="全部",INDEX('3.員工名單'!$H:$H,MATCH(A10,'3.員工名單'!$A:$A,0))="兩款共用",INDEX('3.員工名單'!$H:$H,MATCH(A10,'3.員工名單'!$A:$A,0))=INDEX('1.職能辭典'!$J:$J,MATCH(F10,'1.職能辭典'!$C:$C,0))),OR(INDEX('1.職能辭典'!$K:$K,MATCH(F10,'1.職能辭典'!$C:$C,0))="全部",SUMPRODUCT(ISNUMBER(SEARCH({"經營","管理","財務","企劃","營運","技術","數據","美術","測試","客服"},INDEX('3.員工名單'!$I:$I,MATCH(A10,'3.員工名單'!$A:$A,0))))*ISNUMBER(SEARCH({"經營","管理","財務","企劃","營運","技術","數據","美術","測試","客服"},INDEX('1.職能辭典'!$K:$K,MATCH(F10,'1.職能辭典'!$C:$C,0)))))>0)),INDEX('2.職務職能需求'!$B$2:$F$28,MATCH(F10,'2.職務職能需求'!$A$2:$A$28,0),MATCH(D10,'2.職務職能需求'!$B$1:$F$1,0)),0),""))} | J10: =IF(OR(G10="",I10="",G10=0),"",I10-G10) | K10: =IF(G10="","",IF(G10=0,"不適用",IF(I10="","待評核",IF(I10>=G10,IF(I10>G10,"超越","達標"),"待發展"))))
B11: {=IF(A11="","",IFERROR(INDEX('3.員工名單'!$B:$B,MATCH(A11,'3.員工名單'!$A:$A,0)),"查無此員工"))} | C11: {=IF(A11="","",IFERROR(INDEX('3.員工名單'!$C:$C,MATCH(A11,'3.員工名單'!$A:$A,0)),""))} | D11: {=IF(A11="","",IFERROR(INDEX('3.員工名單'!$D:$D,MATCH(A11,'3.員工名單'!$A:$A,0)),""))} | E11: {=IF(F11="","",IFERROR(INDEX('1.職能辭典'!$A:$A,MATCH(F11,'1.職能辭典'!$C:$C,0)),""))} | G11: {=IF(OR(D11="",F11=""),"",IFERROR(IF(AND(OR(INDEX('1.職能辭典'!$J:$J,MATCH(F11,'1.職能辭典'!$C:$C,0))="全部",INDEX('3.員工名單'!$H:$H,MATCH(A11,'3.員工名單'!$A:$A,0))="兩款共用",INDEX('3.員工名單'!$H:$H,MATCH(A11,'3.員工名單'!$A:$A,0))=INDEX('1.職能辭典'!$J:$J,MATCH(F11,'1.職能辭典'!$C:$C,0))),OR(INDEX('1.職能辭典'!$K:$K,MATCH(F11,'1.職能辭典'!$C:$C,0))="全部",SUMPRODUCT(ISNUMBER(SEARCH({"經營","管理","財務","企劃","營運","技術","數據","美術","測試","客服"},INDEX('3.員工名單'!$I:$I,MATCH(A11,'3.員工名單'!$A:$A,0))))*ISNUMBER(SEARCH({"經營","管理","財務","企劃","營運","技術","數據","美術","測試","客服"},INDEX('1.職能辭典'!$K:$K,MATCH(F11,'1.職能辭典'!$C:$C,0)))))>0)),INDEX('2.職務職能需求'!$B$2:$F$28,MATCH(F11,'2.職務職能需求'!$A$2:$A$28,0),MATCH(D11,'2.職務職能需求'!$B$1:$F$1,0)),0),""))} | J11: =IF(OR(G11="",I11="",G11=0),"",I11-G11) | K11: =IF(G11="","",IF(G11=0,"不適用",IF(I11="","待評核",IF(I11>=G11,IF(I11>G11,"超越","達標"),"待發展"))))
B12: {=IF(A12="","",IFERROR(INDEX('3.員工名單'!$B:$B,MATCH(A12,'3.員工名單'!$A:$A,0)),"查無此員工"))} | C12: {=IF(A12="","",IFERROR(INDEX('3.員工名單'!$C:$C,MATCH(A12,'3.員工名單'!$A:$A,0)),""))} | D12: {=IF(A12="","",IFERROR(INDEX('3.員工名單'!$D:$D,MATCH(A12,'3.員工名單'!$A:$A,0)),""))} | E12: {=IF(F12="","",IFERROR(INDEX('1.職能辭典'!$A:$A,MATCH(F12,'1.職能辭典'!$C:$C,0)),""))} | G12: {=IF(OR(D12="",F12=""),"",IFERROR(IF(AND(OR(INDEX('1.職能辭典'!$J:$J,MATCH(F12,'1.職能辭典'!$C:$C,0))="全部",INDEX('3.員工名單'!$H:$H,MATCH(A12,'3.員工名單'!$A:$A,0))="兩款共用",INDEX('3.員工名單'!$H:$H,MATCH(A12,'3.員工名單'!$A:$A,0))=INDEX('1.職能辭典'!$J:$J,MATCH(F12,'1.職能辭典'!$C:$C,0))),OR(INDEX('1.職能辭典'!$K:$K,MATCH(F12,'1.職能辭典'!$C:$C,0))="全部",SUMPRODUCT(ISNUMBER(SEARCH({"經營","管理","財務","企劃","營運","技術","數據","美術","測試","客服"},INDEX('3.員工名單'!$I:$I,MATCH(A12,'3.員工名單'!$A:$A,0))))*ISNUMBER(SEARCH({"經營","管理","財務","企劃","營運","技術","數據","美術","測試","客服"},INDEX('1.職能辭典'!$K:$K,MATCH(F12,'1.職能辭典'!$C:$C,0)))))>0)),INDEX('2.職務職能需求'!$B$2:$F$28,MATCH(F12,'2.職務職能需求'!$A$2:$A$28,0),MATCH(D12,'2.職務職能需求'!$B$1:$F$1,0)),0),""))} | J12: =IF(OR(G12="",I12="",G12=0),"",I12-G12) | K12: =IF(G12="","",IF(G12=0,"不適用",IF(I12="","待評核",IF(I12>=G12,IF(I12>G12,"超越","達標"),"待發展"))))
B13: {=IF(A13="","",IFERROR(INDEX('3.員工名單'!$B:$B,MATCH(A13,'3.員工名單'!$A:$A,0)),"查無此員工"))} | C13: {=IF(A13="","",IFERROR(INDEX('3.員工名單'!$C:$C,MATCH(A13,'3.員工名單'!$A:$A,0)),""))} | D13: {=IF(A13="","",IFERROR(INDEX('3.員工名單'!$D:$D,MATCH(A13,'3.員工名單'!$A:$A,0)),""))} | E13: {=IF(F13="","",IFERROR(INDEX('1.職能辭典'!$A:$A,MATCH(F13,'1.職能辭典'!$C:$C,0)),""))} | G13: {=IF(OR(D13="",F13=""),"",IFERROR(IF(AND(OR(INDEX('1.職能辭典'!$J:$J,MATCH(F13,'1.職能辭典'!$C:$C,0))="全部",INDEX('3.員工名單'!$H:$H,MATCH(A13,'3.員工名單'!$A:$A,0))="兩款共用",INDEX('3.員工名單'!$H:$H,MATCH(A13,'3.員工名單'!$A:$A,0))=INDEX('1.職能辭典'!$J:$J,MATCH(F13,'1.職能辭典'!$C:$C,0))),OR(INDEX('1.職能辭典'!$K:$K,MATCH(F13,'1.職能辭典'!$C:$C,0))="全部",SUMPRODUCT(ISNUMBER(SEARCH({"經營","管理","財務","企劃","營運","技術","數據","美術","測試","客服"},INDEX('3.員工名單'!$I:$I,MATCH(A13,'3.員工名單'!$A:$A,0))))*ISNUMBER(SEARCH({"經營","管理","財務","企劃","營運","技術","數據","美術","測試","客服"},INDEX('1.職能辭典'!$K:$K,MATCH(F13,'1.職能辭典'!$C:$C,0)))))>0)),INDEX('2.職務職能需求'!$B$2:$F$28,MATCH(F13,'2.職務職能需求'!$A$2:$A$28,0),MATCH(D13,'2.職務職能需求'!$B$1:$F$1,0)),0),""))} | J13: =IF(OR(G13="",I13="",G13=0),"",I13-G13) | K13: =IF(G13="","",IF(G13=0,"不適用",IF(I13="","待評核",IF(I13>=G13,IF(I13>G13,"超越","達標"),"待發展"))))
... B1486: {=IF(A1486="","",IFERROR(INDEX('3.員工名單'!$B:$B,MATCH(A1486,'3.員工名單'!$A:$A,0)),"查無此員工"))} | C1486: {=IF(A1486="","",IFERROR(INDEX('3.員工名單'!$C:$C,MATCH(A1486,'3.員工名單'!$A:$A,0)),""))} | D1486: {=IF(A1486="","",IFERROR(INDEX('3.員工名單'!$D:$D,MATCH(A1486,'3.員工名單'!$A:$A,0)),""))} | E1486: {=IF(F1486="","",IFERROR(INDEX('1.職能辭典'!$A:$A,MATCH(F1486,'1.職能辭典'!$C:$C,0)),""))} | G1486: {=IF(OR(D1486="",F1486=""),"",IFERROR(IF(AND(OR(INDEX('1.職能辭典'!$J:$J,MATCH(F1486,'1.職能辭典'!$C:$C,0))="全部",INDEX('3.員工名單'!$H:$H,MATCH(A1486,'3.員工名單'!$A:$A,0))="兩款共用",INDEX('3.員工名單'!$H:$H,MATCH(A1486,'3.員工名單'!$A:$A,0))=INDEX('1.職能辭典'!$J:$J,MATCH(F1486,'1.職能辭典'!$C:$C,0))),OR(INDEX('1.職能辭典'!$K:$K,MATCH(F1486,'1.職能辭典'!$C:$C,0))="全部",SUMPRODUCT(ISNUMBER(SEARCH({"經營","管理","財務","企劃","營運","技術","數據","美術","測試","客服"},INDEX('3.員工名單'!$I:$I,MATCH(A1486,'3.員工名單'!$A:$A,0))))*ISNUMBER(SEARCH({"經營","管理","財務","企劃","營運","技術","數據","美術","測試","客服"},INDEX('1.職能辭典'!$K:$K,MATCH(F1486,'1.職能辭典'!$C:$C,0)))))>0)),INDEX('2.職務職能需求'!$B$2:$F$28,MATCH(F1486,'2.職務職能需求'!$A$2:$A$28,0),MATCH(D1486,'2.職務職能需求'!$B$1:$F$1,0)),0),""))} | J1486: =IF(OR(G1486="",I1486="",G1486=0),"",I1486-G1486) | K1486: =IF(G1486="","",IF(G1486=0,"不適用",IF(I1486="","待評核",IF(I1486>=G1486,IF(I1486>G1486,"超越","達標"),"待發展"))))

Sheet 5.個人彙總(自動計算)
A1: 員工編號 | B1: 姓名 | C1: 部門 | D1: 職稱 | E1: 已評項目數 | F1: 達標＋超越數 | G1: 待發展數 | H1: 職能達成率 | I1: 平均差距 | J1: 核心職能平均(主管評) | K1: 管理職能平均(主管評) | L1: 專業職能平均(主管評) | M1: 盤點結果
A2: =IF('3.員工名單'!A2="","",'3.員工名單'!A2) | B2: =IF(A2="","",'3.員工名單'!B2) | C2: =IF(A2="","",'3.員工名單'!C2) | D2: =IF(A2="","",'3.員工名單'!D2) | E2: =IF(A2="","",COUNTIFS('4.個人職能盤點'!$A$2:$A$1486,A2,'4.個人職能盤點'!$K$2:$K$1486,"達標")+COUNTIFS('4.個人職能盤點'!$A$2:$A$1486,A2,'4.個人職能盤點'!$K$2:$K$1486,"超越")+COUNTIFS('4.個人職能盤點'!$A$2:$A$1486,A2,'4.個人職能盤點'!$K$2:$K$1486,"待發展")) | F2: =IF(A2="","",COUNTIFS('4.個人職能盤點'!$A$2:$A$1486,A2,'4.個人職能盤點'!$K$2:$K$1486,"達標")+COUNTIFS('4.個人職能盤點'!$A$2:$A$1486,A2,'4.個人職能盤點'!$K$2:$K$1486,"超越")) | G2: =IF(A2="","",COUNTIFS('4.個人職能盤點'!$A$2:$A$1486,A2,'4.個人職能盤點'!$K$2:$K$1486,"待發展")) | H2: =IF(OR(A2="",E2=0),"",F2/E2) | I2: =IF(OR(A2="",E2=0),"",IFERROR(AVERAGEIFS('4.個人職能盤點'!$J$2:$J$1486,'4.個人職能盤點'!$A$2:$A$1486,A2),"")) | J2: =IF(A2="","",IFERROR(AVERAGEIFS('4.個人職能盤點'!$I$2:$I$1486,'4.個人職能盤點'!$A$2:$A$1486,A2,'4.個人職能盤點'!$E$2:$E$1486,"核心職能",'4.個人職能盤點'!$G$2:$G$1486,">0"),"-")) | K2: =IF(A2="","",IFERROR(AVERAGEIFS('4.個人職能盤點'!$I$2:$I$1486,'4.個人職能盤點'!$A$2:$A$1486,A2,'4.個人職能盤點'!$E$2:$E$1486,"管理職能",'4.個人職能盤點'!$G$2:$G$1486,">0"),"-")) | L2: =IF(A2="","",IFERROR(AVERAGEIFS('4.個人職能盤點'!$I$2:$I$1486,'4.個人職能盤點'!$A$2:$A$1486,A2,'4.個人職能盤點'!$E$2:$E$1486,"專業職能",'4.個人職能盤點'!$G$2:$G$1486,">0"),"-")) | M2: =IF(H2="","",IF(H2>=0.9,"優秀",IF(H2>=0.7,"符合期待","需加強發展")))
A3: =IF('3.員工名單'!A4="","",'3.員工名單'!A4) | B3: =IF(A3="","",'3.員工名單'!B4) | C3: =IF(A3="","",'3.員工名單'!C4) | D3: =IF(A3="","",'3.員工名單'!D4) | E3: =IF(A3="","",COUNTIFS('4.個人職能盤點'!$A$2:$A$1486,A3,'4.個人職能盤點'!$K$2:$K$1486,"達標")+COUNTIFS('4.個人職能盤點'!$A$2:$A$1486,A3,'4.個人職能盤點'!$K$2:$K$1486,"超越")+COUNTIFS('4.個人職能盤點'!$A$2:$A$1486,A3,'4.個人職能盤點'!$K$2:$K$1486,"待發展")) | F3: =IF(A3="","",COUNTIFS('4.個人職能盤點'!$A$2:$A$1486,A3,'4.個人職能盤點'!$K$2:$K$1486,"達標")+COUNTIFS('4.個人職能盤點'!$A$2:$A$1486,A3,'4.個人職能盤點'!$K$2:$K$1486,"超越")) | G3: =IF(A3="","",COUNTIFS('4.個人職能盤點'!$A$2:$A$1486,A3,'4.個人職能盤點'!$K$2:$K$1486,"待發展")) | H3: =IF(OR(A3="",E3=0),"",F3/E3) | I3: =IF(OR(A3="",E3=0),"",IFERROR(AVERAGEIFS('4.個人職能盤點'!$J$2:$J$1486,'4.個人職能盤點'!$A$2:$A$1486,A3),"")) | J3: =IF(A3="","",IFERROR(AVERAGEIFS('4.個人職能盤點'!$I$2:$I$1486,'4.個人職能盤點'!$A$2:$A$1486,A3,'4.個人職能盤點'!$E$2:$E$1486,"核心職能",'4.個人職能盤點'!$G$2:$G$1486,">0"),"-")) | K3: =IF(A3="","",IFERROR(AVERAGEIFS('4.個人職能盤點'!$I$2:$I$1486,'4.個人職能盤點'!$A$2:$A$1486,A3,'4.個人職能盤點'!$E$2:$E$1486,"管理職能",'4.個人職能盤點'!$G$2:$G$1486,">0"),"-")) | L3: =IF(A3="","",IFERROR(AVERAGEIFS('4.個人職能盤點'!$I$2:$I$1486,'4.個人職能盤點'!$A$2:$A$1486,A3,'4.個人職能盤點'!$E$2:$E$1486,"專業職能",'4.個人職能盤點'!$G$2:$G$1486,">0"),"-")) | M3: =IF(H3="","",IF(H3>=0.9,"優秀",IF(H3>=0.7,"符合期待","需加強發展")))
A4: =IF('3.員工名單'!A5="","",'3.員工名單'!A5) | B4: =IF(A4="","",'3.員工名單'!B5) | C4: =IF(A4="","",'3.員工名單'!C5) | D4: =IF(A4="","",'3.員工名單'!D5) | E4: =IF(A4="","",COUNTIFS('4.個人職能盤點'!$A$2:$A$1486,A4,'4.個人職能盤點'!$K$2:$K$1486,"達標")+COUNTIFS('4.個人職能盤點'!$A$2:$A$1486,A4,'4.個人職能盤點'!$K$2:$K$1486,"超越")+COUNTIFS('4.個人職能盤點'!$A$2:$A$1486,A4,'4.個人職能盤點'!$K$2:$K$1486,"待發展")) | F4: =IF(A4="","",COUNTIFS('4.個人職能盤點'!$A$2:$A$1486,A4,'4.個人職能盤點'!$K$2:$K$1486,"達標")+COUNTIFS('4.個人職能盤點'!$A$2:$A$1486,A4,'4.個人職能盤點'!$K$2:$K$1486,"超越")) | G4: =IF(A4="","",COUNTIFS('4.個人職能盤點'!$A$2:$A$1486,A4,'4.個人職能盤點'!$K$2:$K$1486,"待發展")) | H4: =IF(OR(A4="",E4=0),"",F4/E4) | I4: =IF(OR(A4="",E4=0),"",IFERROR(AVERAGEIFS('4.個人職能盤點'!$J$2:$J$1486,'4.個人職能盤點'!$A$2:$A$1486,A4),"")) | J4: =IF(A4="","",IFERROR(AVERAGEIFS('4.個人職能盤點'!$I$2:$I$1486,'4.個人職能盤點'!$A$2:$A$1486,A4,'4.個人職能盤點'!$E$2:$E$1486,"核心職能",'4.個人職能盤點'!$G$2:$G$1486,">0"),"-")) | K4: =IF(A4="","",IFERROR(AVERAGEIFS('4.個人職能盤點'!$I$2:$I$1486,'4.個人職能盤點'!$A$2:$A$1486,A4,'4.個人職能盤點'!$E$2:$E$1486,"管理職能",'4.個人職能盤點'!$G$2:$G$1486,">0"),"-")) | L4: =IF(A4="","",IFERROR(AVERAGEIFS('4.個人職能盤點'!$I$2:$I$1486,'4.個人職能盤點'!$A$2:$A$1486,A4,'4.個人職能盤點'!$E$2:$E$1486,"專業職能",'4.個人職能盤點'!$G$2:$G$1486,">0"),"-")) | M4: =IF(H4="","",IF(H4>=0.9,"優秀",IF(H4>=0.7,"符合期待","需加強發展")))
A5: =IF('3.員工名單'!A6="","",'3.員工名單'!A6) | B5: =IF(A5="","",'3.員工名單'!B6) | C5: =IF(A5="","",'3.員工名單'!C6) | D5: =IF(A5="","",'3.員工名單'!D6) | E5: =IF(A5="","",COUNTIFS('4.個人職能盤點'!$A$2:$A$1486,A5,'4.個人職能盤點'!$K$2:$K$1486,"達標")+COUNTIFS('4.個人職能盤點'!$A$2:$A$1486,A5,'4.個人職能盤點'!$K$2:$K$1486,"超越")+COUNTIFS('4.個人職能盤點'!$A$2:$A$1486,A5,'4.個人職能盤點'!$K$2:$K$1486,"待發展")) | F5: =IF(A5="","",COUNTIFS('4.個人職能盤點'!$A$2:$A$1486,A5,'4.個人職能盤點'!$K$2:$K$1486,"達標")+COUNTIFS('4.個人職能盤點'!$A$2:$A$1486,A5,'4.個人職能盤點'!$K$2:$K$1486,"超越")) | G5: =IF(A5="","",COUNTIFS('4.個人職能盤點'!$A$2:$A$1486,A5,'4.個人職能盤點'!$K$2:$K$1486,"待發展")) | H5: =IF(OR(A5="",E5=0),"",F5/E5) | I5: =IF(OR(A5="",E5=0),"",IFERROR(AVERAGEIFS('4.個人職能盤點'!$J$2:$J$1486,'4.個人職能盤點'!$A$2:$A$1486,A5),"")) | J5: =IF(A5="","",IFERROR(AVERAGEIFS('4.個人職能盤點'!$I$2:$I$1486,'4.個人職能盤點'!$A$2:$A$1486,A5,'4.個人職能盤點'!$E$2:$E$1486,"核心職能",'4.個人職能盤點'!$G$2:$G$1486,">0"),"-")) | K5: =IF(A5="","",IFERROR(AVERAGEIFS('4.個人職能盤點'!$I$2:$I$1486,'4.個人職能盤點'!$A$2:$A$1486,A5,'4.個人職能盤點'!$E$2:$E$1486,"管理職能",'4.個人職能盤點'!$G$2:$G$1486,">0"),"-")) | L5: =IF(A5="","",IFERROR(AVERAGEIFS('4.個人職能盤點'!$I$2:$I$1486,'4.個人職能盤點'!$A$2:$A$1486,A5,'4.個人職能盤點'!$E$2:$E$1486,"專業職能",'4.個人職能盤點'!$G$2:$G$1486,">0"),"-")) | M5: =IF(H5="","",IF(H5>=0.9,"優秀",IF(H5>=0.7,"符合期待","需加強發展")))
A6: =IF('3.員工名單'!A7="","",'3.員工名單'!A7) | B6: =IF(A6="","",'3.員工名單'!B7) | C6: =IF(A6="","",'3.員工名單'!C7) | D6: =IF(A6="","",'3.員工名單'!D7) | E6: =IF(A6="","",COUNTIFS('4.個人職能盤點'!$A$2:$A$1486,A6,'4.個人職能盤點'!$K$2:$K$1486,"達標")+COUNTIFS('4.個人職能盤點'!$A$2:$A$1486,A6,'4.個人職能盤點'!$K$2:$K$1486,"超越")+COUNTIFS('4.個人職能盤點'!$A$2:$A$1486,A6,'4.個人職能盤點'!$K$2:$K$1486,"待發展")) | F6: =IF(A6="","",COUNTIFS('4.個人職能盤點'!$A$2:$A$1486,A6,'4.個人職能盤點'!$K$2:$K$1486,"達標")+COUNTIFS('4.個人職能盤點'!$A$2:$A$1486,A6,'4.個人職能盤點'!$K$2:$K$1486,"超越")) | G6: =IF(A6="","",COUNTIFS('4.個人職能盤點'!$A$2:$A$1486,A6,'4.個人職能盤點'!$K$2:$K$1486,"待發展")) | H6: =IF(OR(A6="",E6=0),"",F6/E6) | I6: =IF(OR(A6="",E6=0),"",IFERROR(AVERAGEIFS('4.個人職能盤點'!$J$2:$J$1486,'4.個人職能盤點'!$A$2:$A$1486,A6),"")) | J6: =IF(A6="","",IFERROR(AVERAGEIFS('4.個人職能盤點'!$I$2:$I$1486,'4.個人職能盤點'!$A$2:$A$1486,A6,'4.個人職能盤點'!$E$2:$E$1486,"核心職能",'4.個人職能盤點'!$G$2:$G$1486,">0"),"-")) | K6: =IF(A6="","",IFERROR(AVERAGEIFS('4.個人職能盤點'!$I$2:$I$1486,'4.個人職能盤點'!$A$2:$A$1486,A6,'4.個人職能盤點'!$E$2:$E$1486,"管理職能",'4.個人職能盤點'!$G$2:$G$1486,">0"),"-")) | L6: =IF(A6="","",IFERROR(AVERAGEIFS('4.個人職能盤點'!$I$2:$I$1486,'4.個人職能盤點'!$A$2:$A$1486,A6,'4.個人職能盤點'!$E$2:$E$1486,"專業職能",'4.個人職能盤點'!$G$2:$G$1486,">0"),"-")) | M6: =IF(H6="","",IF(H6>=0.9,"優秀",IF(H6>=0.7,"符合期待","需加強發展")))
A7: =IF('3.員工名單'!A8="","",'3.員工名單'!A8) | B7: =IF(A7="","",'3.員工名單'!B8) | C7: =IF(A7="","",'3.員工名單'!C8) | D7: =IF(A7="","",'3.員工名單'!D8) | E7: =IF(A7="","",COUNTIFS('4.個人職能盤點'!$A$2:$A$1486,A7,'4.個人職能盤點'!$K$2:$K$1486,"達標")+COUNTIFS('4.個人職能盤點'!$A$2:$A$1486,A7,'4.個人職能盤點'!$K$2:$K$1486,"超越")+COUNTIFS('4.個人職能盤點'!$A$2:$A$1486,A7,'4.個人職能盤點'!$K$2:$K$1486,"待發展")) | F7: =IF(A7="","",COUNTIFS('4.個人職能盤點'!$A$2:$A$1486,A7,'4.個人職能盤點'!$K$2:$K$1486,"達標")+COUNTIFS('4.個人職能盤點'!$A$2:$A$1486,A7,'4.個人職能盤點'!$K$2:$K$1486,"超越")) | G7: =IF(A7="","",COUNTIFS('4.個人職能盤點'!$A$2:$A$1486,A7,'4.個人職能盤點'!$K$2:$K$1486,"待發展")) | H7: =IF(OR(A7="",E7=0),"",F7/E7) | I7: =IF(OR(A7="",E7=0),"",IFERROR(AVERAGEIFS('4.個人職能盤點'!$J$2:$J$1486,'4.個人職能盤點'!$A$2:$A$1486,A7),"")) | J7: =IF(A7="","",IFERROR(AVERAGEIFS('4.個人職能盤點'!$I$2:$I$1486,'4.個人職能盤點'!$A$2:$A$1486,A7,'4.個人職能盤點'!$E$2:$E$1486,"核心職能",'4.個人職能盤點'!$G$2:$G$1486,">0"),"-")) | K7: =IF(A7="","",IFERROR(AVERAGEIFS('4.個人職能盤點'!$I$2:$I$1486,'4.個人職能盤點'!$A$2:$A$1486,A7,'4.個人職能盤點'!$E$2:$E$1486,"管理職能",'4.個人職能盤點'!$G$2:$G$1486,">0"),"-")) | L7: =IF(A7="","",IFERROR(AVERAGEIFS('4.個人職能盤點'!$I$2:$I$1486,'4.個人職能盤點'!$A$2:$A$1486,A7,'4.個人職能盤點'!$E$2:$E$1486,"專業職能",'4.個人職能盤點'!$G$2:$G$1486,">0"),"-")) | M7: =IF(H7="","",IF(H7>=0.9,"優秀",IF(H7>=0.7,"符合期待","需加強發展")))
A8: =IF('3.員工名單'!A9="","",'3.員工名單'!A9) | B8: =IF(A8="","",'3.員工名單'!B9) | C8: =IF(A8="","",'3.員工名單'!C9) | D8: =IF(A8="","",'3.員工名單'!D9) | E8: =IF(A8="","",COUNTIFS('4.個人職能盤點'!$A$2:$A$1486,A8,'4.個人職能盤點'!$K$2:$K$1486,"達標")+COUNTIFS('4.個人職能盤點'!$A$2:$A$1486,A8,'4.個人職能盤點'!$K$2:$K$1486,"超越")+COUNTIFS('4.個人職能盤點'!$A$2:$A$1486,A8,'4.個人職能盤點'!$K$2:$K$1486,"待發展")) | F8: =IF(A8="","",COUNTIFS('4.個人職能盤點'!$A$2:$A$1486,A8,'4.個人職能盤點'!$K$2:$K$1486,"達標")+COUNTIFS('4.個人職能盤點'!$A$2:$A$1486,A8,'4.個人職能盤點'!$K$2:$K$1486,"超越")) | G8: =IF(A8="","",COUNTIFS('4.個人職能盤點'!$A$2:$A$1486,A8,'4.個人職能盤點'!$K$2:$K$1486,"待發展")) | H8: =IF(OR(A8="",E8=0),"",F8/E8) | I8: =IF(OR(A8="",E8=0),"",IFERROR(AVERAGEIFS('4.個人職能盤點'!$J$2:$J$1486,'4.個人職能盤點'!$A$2:$A$1486,A8),"")) | J8: =IF(A8="","",IFERROR(AVERAGEIFS('4.個人職能盤點'!$I$2:$I$1486,'4.個人職能盤點'!$A$2:$A$1486,A8,'4.個人職能盤點'!$E$2:$E$1486,"核心職能",'4.個人職能盤點'!$G$2:$G$1486,">0"),"-")) | K8: =IF(A8="","",IFERROR(AVERAGEIFS('4.個人職能盤點'!$I$2:$I$1486,'4.個人職能盤點'!$A$2:$A$1486,A8,'4.個人職能盤點'!$E$2:$E$1486,"管理職能",'4.個人職能盤點'!$G$2:$G$1486,">0"),"-")) | L8: =IF(A8="","",IFERROR(AVERAGEIFS('4.個人職能盤點'!$I$2:$I$1486,'4.個人職能盤點'!$A$2:$A$1486,A8,'4.個人職能盤點'!$E$2:$E$1486,"專業職能",'4.個人職能盤點'!$G$2:$G$1486,">0"),"-")) | M8: =IF(H8="","",IF(H8>=0.9,"優秀",IF(H8>=0.7,"符合期待","需加強發展")))
A9: =IF('3.員工名單'!A10="","",'3.員工名單'!A10) | B9: =IF(A9="","",'3.員工名單'!B10) | C9: =IF(A9="","",'3.員工名單'!C10) | D9: =IF(A9="","",'3.員工名單'!D10) | E9: =IF(A9="","",COUNTIFS('4.個人職能盤點'!$A$2:$A$1486,A9,'4.個人職能盤點'!$K$2:$K$1486,"達標")+COUNTIFS('4.個人職能盤點'!$A$2:$A$1486,A9,'4.個人職能盤點'!$K$2:$K$1486,"超越")+COUNTIFS('4.個人職能盤點'!$A$2:$A$1486,A9,'4.個人職能盤點'!$K$2:$K$1486,"待發展")) | F9: =IF(A9="","",COUNTIFS('4.個人職能盤點'!$A$2:$A$1486,A9,'4.個人職能盤點'!$K$2:$K$1486,"達標")+COUNTIFS('4.個人職能盤點'!$A$2:$A$1486,A9,'4.個人職能盤點'!$K$2:$K$1486,"超越")) | G9: =IF(A9="","",COUNTIFS('4.個人職能盤點'!$A$2:$A$1486,A9,'4.個人職能盤點'!$K$2:$K$1486,"待發展")) | H9: =IF(OR(A9="",E9=0),"",F9/E9) | I9: =IF(OR(A9="",E9=0),"",IFERROR(AVERAGEIFS('4.個人職能盤點'!$J$2:$J$1486,'4.個人職能盤點'!$A$2:$A$1486,A9),"")) | J9: =IF(A9="","",IFERROR(AVERAGEIFS('4.個人職能盤點'!$I$2:$I$1486,'4.個人職能盤點'!$A$2:$A$1486,A9,'4.個人職能盤點'!$E$2:$E$1486,"核心職能",'4.個人職能盤點'!$G$2:$G$1486,">0"),"-")) | K9: =IF(A9="","",IFERROR(AVERAGEIFS('4.個人職能盤點'!$I$2:$I$1486,'4.個人職能盤點'!$A$2:$A$1486,A9,'4.個人職能盤點'!$E$2:$E$1486,"管理職能",'4.個人職能盤點'!$G$2:$G$1486,">0"),"-")) | L9: =IF(A9="","",IFERROR(AVERAGEIFS('4.個人職能盤點'!$I$2:$I$1486,'4.個人職能盤點'!$A$2:$A$1486,A9,'4.個人職能盤點'!$E$2:$E$1486,"專業職能",'4.個人職能盤點'!$G$2:$G$1486,">0"),"-")) | M9: =IF(H9="","",IF(H9>=0.9,"優秀",IF(H9>=0.7,"符合期待","需加強發展")))
A10: =IF('3.員工名單'!A11="","",'3.員工名單'!A11) | B10: =IF(A10="","",'3.員工名單'!B11) | C10: =IF(A10="","",'3.員工名單'!C11) | D10: =IF(A10="","",'3.員工名單'!D11) | E10: =IF(A10="","",COUNTIFS('4.個人職能盤點'!$A$2:$A$1486,A10,'4.個人職能盤點'!$K$2:$K$1486,"達標")+COUNTIFS('4.個人職能盤點'!$A$2:$A$1486,A10,'4.個人職能盤點'!$K$2:$K$1486,"超越")+COUNTIFS('4.個人職能盤點'!$A$2:$A$1486,A10,'4.個人職能盤點'!$K$2:$K$1486,"待發展")) | F10: =IF(A10="","",COUNTIFS('4.個人職能盤點'!$A$2:$A$1486,A10,'4.個人職能盤點'!$K$2:$K$1486,"達標")+COUNTIFS('4.個人職能盤點'!$A$2:$A$1486,A10,'4.個人職能盤點'!$K$2:$K$1486,"超越")) | G10: =IF(A10="","",COUNTIFS('4.個人職能盤點'!$A$2:$A$1486,A10,'4.個人職能盤點'!$K$2:$K$1486,"待發展")) | H10: =IF(OR(A10="",E10=0),"",F10/E10) | I10: =IF(OR(A10="",E10=0),"",IFERROR(AVERAGEIFS('4.個人職能盤點'!$J$2:$J$1486,'4.個人職能盤點'!$A$2:$A$1486,A10),"")) | J10: =IF(A10="","",IFERROR(AVERAGEIFS('4.個人職能盤點'!$I$2:$I$1486,'4.個人職能盤點'!$A$2:$A$1486,A10,'4.個人職能盤點'!$E$2:$E$1486,"核心職能",'4.個人職能盤點'!$G$2:$G$1486,">0"),"-")) | K10: =IF(A10="","",IFERROR(AVERAGEIFS('4.個人職能盤點'!$I$2:$I$1486,'4.個人職能盤點'!$A$2:$A$1486,A10,'4.個人職能盤點'!$E$2:$E$1486,"管理職能",'4.個人職能盤點'!$G$2:$G$1486,">0"),"-")) | L10: =IF(A10="","",IFERROR(AVERAGEIFS('4.個人職能盤點'!$I$2:$I$1486,'4.個人職能盤點'!$A$2:$A$1486,A10,'4.個人職能盤點'!$E$2:$E$1486,"專業職能",'4.個人職能盤點'!$G$2:$G$1486,">0"),"-")) | M10: =IF(H10="","",IF(H10>=0.9,"優秀",IF(H10>=0.7,"符合期待","需加強發展")))
A11: =IF('3.員工名單'!A12="","",'3.員工名單'!A12) | B11: =IF(A11="","",'3.員工名單'!B12) | C11: =IF(A11="","",'3.員工名單'!C12) | D11: =IF(A11="","",'3.員工名單'!D12) | E11: =IF(A11="","",COUNTIFS('4.個人職能盤點'!$A$2:$A$1486,A11,'4.個人職能盤點'!$K$2:$K$1486,"達標")+COUNTIFS('4.個人職能盤點'!$A$2:$A$1486,A11,'4.個人職能盤點'!$K$2:$K$1486,"超越")+COUNTIFS('4.個人職能盤點'!$A$2:$A$1486,A11,'4.個人職能盤點'!$K$2:$K$1486,"待發展")) | F11: =IF(A11="","",COUNTIFS('4.個人職能盤點'!$A$2:$A$1486,A11,'4.個人職能盤點'!$K$2:$K$1486,"達標")+COUNTIFS('4.個人職能盤點'!$A$2:$A$1486,A11,'4.個人職能盤點'!$K$2:$K$1486,"超越")) | G11: =IF(A11="","",COUNTIFS('4.個人職能盤點'!$A$2:$A$1486,A11,'4.個人職能盤點'!$K$2:$K$1486,"待發展")) | H11: =IF(OR(A11="",E11=0),"",F11/E11) | I11: =IF(OR(A11="",E11=0),"",IFERROR(AVERAGEIFS('4.個人職能盤點'!$J$2:$J$1486,'4.個人職能盤點'!$A$2:$A$1486,A11),"")) | J11: =IF(A11="","",IFERROR(AVERAGEIFS('4.個人職能盤點'!$I$2:$I$1486,'4.個人職能盤點'!$A$2:$A$1486,A11,'4.個人職能盤點'!$E$2:$E$1486,"核心職能",'4.個人職能盤點'!$G$2:$G$1486,">0"),"-")) | K11: =IF(A11="","",IFERROR(AVERAGEIFS('4.個人職能盤點'!$I$2:$I$1486,'4.個人職能盤點'!$A$2:$A$1486,A11,'4.個人職能盤點'!$E$2:$E$1486,"管理職能",'4.個人職能盤點'!$G$2:$G$1486,">0"),"-")) | L11: =IF(A11="","",IFERROR(AVERAGEIFS('4.個人職能盤點'!$I$2:$I$1486,'4.個人職能盤點'!$A$2:$A$1486,A11,'4.個人職能盤點'!$E$2:$E$1486,"專業職能",'4.個人職能盤點'!$G$2:$G$1486,">0"),"-")) | M11: =IF(H11="","",IF(H11>=0.9,"優秀",IF(H11>=0.7,"符合期待","需加強發展")))
A12: =IF('3.員工名單'!A13="","",'3.員工名單'!A13) | B12: =IF(A12="","",'3.員工名單'!B13) | C12: =IF(A12="","",'3.員工名單'!C13) | D12: =IF(A12="","",'3.員工名單'!D13) | E12: =IF(A12="","",COUNTIFS('4.個人職能盤點'!$A$2:$A$1486,A12,'4.個人職能盤點'!$K$2:$K$1486,"達標")+COUNTIFS('4.個人職能盤點'!$A$2:$A$1486,A12,'4.個人職能盤點'!$K$2:$K$1486,"超越")+COUNTIFS('4.個人職能盤點'!$A$2:$A$1486,A12,'4.個人職能盤點'!$K$2:$K$1486,"待發展")) | F12: =IF(A12="","",COUNTIFS('4.個人職能盤點'!$A$2:$A$1486,A12,'4.個人職能盤點'!$K$2:$K$1486,"達標")+COUNTIFS('4.個人職能盤點'!$A$2:$A$1486,A12,'4.個人職能盤點'!$K$2:$K$1486,"超越")) | G12: =IF(A12="","",COUNTIFS('4.個人職能盤點'!$A$2:$A$1486,A12,'4.個人職能盤點'!$K$2:$K$1486,"待發展")) | H12: =IF(OR(A12="",E12=0),"",F12/E12) | I12: =IF(OR(A12="",E12=0),"",IFERROR(AVERAGEIFS('4.個人職能盤點'!$J$2:$J$1486,'4.個人職能盤點'!$A$2:$A$1486,A12),"")) | J12: =IF(A12="","",IFERROR(AVERAGEIFS('4.個人職能盤點'!$I$2:$I$1486,'4.個人職能盤點'!$A$2:$A$1486,A12,'4.個人職能盤點'!$E$2:$E$1486,"核心職能",'4.個人職能盤點'!$G$2:$G$1486,">0"),"-")) | K12: =IF(A12="","",IFERROR(AVERAGEIFS('4.個人職能盤點'!$I$2:$I$1486,'4.個人職能盤點'!$A$2:$A$1486,A12,'4.個人職能盤點'!$E$2:$E$1486,"管理職能",'4.個人職能盤點'!$G$2:$G$1486,">0"),"-")) | L12: =IF(A12="","",IFERROR(AVERAGEIFS('4.個人職能盤點'!$I$2:$I$1486,'4.個人職能盤點'!$A$2:$A$1486,A12,'4.個人職能盤點'!$E$2:$E$1486,"專業職能",'4.個人職能盤點'!$G$2:$G$1486,">0"),"-")) | M12: =IF(H12="","",IF(H12>=0.9,"優秀",IF(H12>=0.7,"符合期待","需加強發展")))
A13: =IF('3.員工名單'!A14="","",'3.員工名單'!A14) | B13: =IF(A13="","",'3.員工名單'!B14) | C13: =IF(A13="","",'3.員工名單'!C14) | D13: =IF(A13="","",'3.員工名單'!D14) | E13: =IF(A13="","",COUNTIFS('4.個人職能盤點'!$A$2:$A$1486,A13,'4.個人職能盤點'!$K$2:$K$1486,"達標")+COUNTIFS('4.個人職能盤點'!$A$2:$A$1486,A13,'4.個人職能盤點'!$K$2:$K$1486,"超越")+COUNTIFS('4.個人職能盤點'!$A$2:$A$1486,A13,'4.個人職能盤點'!$K$2:$K$1486,"待發展")) | F13: =IF(A13="","",COUNTIFS('4.個人職能盤點'!$A$2:$A$1486,A13,'4.個人職能盤點'!$K$2:$K$1486,"達標")+COUNTIFS('4.個人職能盤點'!$A$2:$A$1486,A13,'4.個人職能盤點'!$K$2:$K$1486,"超越")) | G13: =IF(A13="","",COUNTIFS('4.個人職能盤點'!$A$2:$A$1486,A13,'4.個人職能盤點'!$K$2:$K$1486,"待發展")) | H13: =IF(OR(A13="",E13=0),"",F13/E13) | I13: =IF(OR(A13="",E13=0),"",IFERROR(AVERAGEIFS('4.個人職能盤點'!$J$2:$J$1486,'4.個人職能盤點'!$A$2:$A$1486,A13),"")) | J13: =IF(A13="","",IFERROR(AVERAGEIFS('4.個人職能盤點'!$I$2:$I$1486,'4.個人職能盤點'!$A$2:$A$1486,A13,'4.個人職能盤點'!$E$2:$E$1486,"核心職能",'4.個人職能盤點'!$G$2:$G$1486,">0"),"-")) | K13: =IF(A13="","",IFERROR(AVERAGEIFS('4.個人職能盤點'!$I$2:$I$1486,'4.個人職能盤點'!$A$2:$A$1486,A13,'4.個人職能盤點'!$E$2:$E$1486,"管理職能",'4.個人職能盤點'!$G$2:$G$1486,">0"),"-")) | L13: =IF(A13="","",IFERROR(AVERAGEIFS('4.個人職能盤點'!$I$2:$I$1486,'4.個人職能盤點'!$A$2:$A$1486,A13,'4.個人職能盤點'!$E$2:$E$1486,"專業職能",'4.個人職能盤點'!$G$2:$G$1486,">0"),"-")) | M13: =IF(H13="","",IF(H13>=0.9,"優秀",IF(H13>=0.7,"符合期待","需加強發展")))
A14: =IF('3.員工名單'!A15="","",'3.員工名單'!A15) | B14: =IF(A14="","",'3.員工名單'!B15) | C14: =IF(A14="","",'3.員工名單'!C15) | D14: =IF(A14="","",'3.員工名單'!D15) | E14: =IF(A14="","",COUNTIFS('4.個人職能盤點'!$A$2:$A$1486,A14,'4.個人職能盤點'!$K$2:$K$1486,"達標")+COUNTIFS('4.個人職能盤點'!$A$2:$A$1486,A14,'4.個人職能盤點'!$K$2:$K$1486,"超越")+COUNTIFS('4.個人職能盤點'!$A$2:$A$1486,A14,'4.個人職能盤點'!$K$2:$K$1486,"待發展")) | F14: =IF(A14="","",COUNTIFS('4.個人職能盤點'!$A$2:$A$1486,A14,'4.個人職能盤點'!$K$2:$K$1486,"達標")+COUNTIFS('4.個人職能盤點'!$A$2:$A$1486,A14,'4.個人職能盤點'!$K$2:$K$1486,"超越")) | G14: =IF(A14="","",COUNTIFS('4.個人職能盤點'!$A$2:$A$1486,A14,'4.個人職能盤點'!$K$2:$K$1486,"待發展")) | H14: =IF(OR(A14="",E14=0),"",F14/E14) | I14: =IF(OR(A14="",E14=0),"",IFERROR(AVERAGEIFS('4.個人職能盤點'!$J$2:$J$1486,'4.個人職能盤點'!$A$2:$A$1486,A14),"")) | J14: =IF(A14="","",IFERROR(AVERAGEIFS('4.個人職能盤點'!$I$2:$I$1486,'4.個人職能盤點'!$A$2:$A$1486,A14,'4.個人職能盤點'!$E$2:$E$1486,"核心職能",'4.個人職能盤點'!$G$2:$G$1486,">0"),"-")) | K14: =IF(A14="","",IFERROR(AVERAGEIFS('4.個人職能盤點'!$I$2:$I$1486,'4.個人職能盤點'!$A$2:$A$1486,A14,'4.個人職能盤點'!$E$2:$E$1486,"管理職能",'4.個人職能盤點'!$G$2:$G$1486,">0"),"-")) | L14: =IF(A14="","",IFERROR(AVERAGEIFS('4.個人職能盤點'!$I$2:$I$1486,'4.個人職能盤點'!$A$2:$A$1486,A14,'4.個人職能盤點'!$E$2:$E$1486,"專業職能",'4.個人職能盤點'!$G$2:$G$1486,">0"),"-")) | M14: =IF(H14="","",IF(H14>=0.9,"優秀",IF(H14>=0.7,"符合期待","需加強發展")))
... A23: =IF('3.員工名單'!A24="","",'3.員工名單'!A24) | B23: =IF(A23="","",'3.員工名單'!B24) | C23: =IF(A23="","",'3.員工名單'!C24) | D23: =IF(A23="","",'3.員工名單'!D24) | E23: =IF(A23="","",COUNTIFS('4.個人職能盤點'!$A$2:$A$1486,A23,'4.個人職能盤點'!$K$2:$K$1486,"達標")+COUNTIFS('4.個人職能盤點'!$A$2:$A$1486,A23,'4.個人職能盤點'!$K$2:$K$1486,"超越")+COUNTIFS('4.個人職能盤點'!$A$2:$A$1486,A23,'4.個人職能盤點'!$K$2:$K$1486,"待發展")) | F23: =IF(A23="","",COUNTIFS('4.個人職能盤點'!$A$2:$A$1486,A23,'4.個人職能盤點'!$K$2:$K$1486,"達標")+COUNTIFS('4.個人職能盤點'!$A$2:$A$1486,A23,'4.個人職能盤點'!$K$2:$K$1486,"超越")) | G23: =IF(A23="","",COUNTIFS('4.個人職能盤點'!$A$2:$A$1486,A23,'4.個人職能盤點'!$K$2:$K$1486,"待發展")) | H23: =IF(OR(A23="",E23=0),"",F23/E23) | I23: =IF(OR(A23="",E23=0),"",IFERROR(AVERAGEIFS('4.個人職能盤點'!$J$2:$J$1486,'4.個人職能盤點'!$A$2:$A$1486,A23),"")) | J23: =IF(A23="","",IFERROR(AVERAGEIFS('4.個人職能盤點'!$I$2:$I$1486,'4.個人職能盤點'!$A$2:$A$1486,A23,'4.個人職能盤點'!$E$2:$E$1486,"核心職能",'4.個人職能盤點'!$G$2:$G$1486,">0"),"-")) | K23: =IF(A23="","",IFERROR(AVERAGEIFS('4.個人職能盤點'!$I$2:$I$1486,'4.個人職能盤點'!$A$2:$A$1486,A23,'4.個人職能盤點'!$E$2:$E$1486,"管理職能",'4.個人職能盤點'!$G$2:$G$1486,">0"),"-")) | L23: =IF(A23="","",IFERROR(AVERAGEIFS('4.個人職能盤點'!$I$2:$I$1486,'4.個人職能盤點'!$A$2:$A$1486,A23,'4.個人職能盤點'!$E$2:$E$1486,"專業職能",'4.個人職能盤點'!$G$2:$G$1486,">0"),"-")) | M23: =IF(H23="","",IF(H23>=0.9,"優秀",IF(H23>=0.7,"符合期待","需加強發展")))
A24: =IF('3.員工名單'!A3="","",'3.員工名單'!A3) | B24: =IF(A24="","",'3.員工名單'!B3) | C24: =IF(A24="","",'3.員工名單'!C3) | D24: =IF(A24="","",'3.員工名單'!D3) | E24: =IF(A24="","",COUNTIFS('4.個人職能盤點'!$A$2:$A$1486,A24,'4.個人職能盤點'!$K$2:$K$1486,"達標")+COUNTIFS('4.個人職能盤點'!$A$2:$A$1486,A24,'4.個人職能盤點'!$K$2:$K$1486,"超越")+COUNTIFS('4.個人職能盤點'!$A$2:$A$1486,A24,'4.個人職能盤點'!$K$2:$K$1486,"待發展")) | F24: =IF(A24="","",COUNTIFS('4.個人職能盤點'!$A$2:$A$1486,A24,'4.個人職能盤點'!$K$2:$K$1486,"達標")+COUNTIFS('4.個人職能盤點'!$A$2:$A$1486,A24,'4.個人職能盤點'!$K$2:$K$1486,"超越")) | G24: =IF(A24="","",COUNTIFS('4.個人職能盤點'!$A$2:$A$1486,A24,'4.個人職能盤點'!$K$2:$K$1486,"待發展")) | H24: =IF(OR(A24="",E24=0),"",F24/E24) | I24: =IF(OR(A24="",E24=0),"",IFERROR(AVERAGEIFS('4.個人職能盤點'!$J$2:$J$1486,'4.個人職能盤點'!$A$2:$A$1486,A24),"")) | J24: =IF(A24="","",IFERROR(AVERAGEIFS('4.個人職能盤點'!$I$2:$I$1486,'4.個人職能盤點'!$A$2:$A$1486,A24,'4.個人職能盤點'!$E$2:$E$1486,"核心職能",'4.個人職能盤點'!$G$2:$G$1486,">0"),"-")) | K24: =IF(A24="","",IFERROR(AVERAGEIFS('4.個人職能盤點'!$I$2:$I$1486,'4.個人職能盤點'!$A$2:$A$1486,A24,'4.個人職能盤點'!$E$2:$E$1486,"管理職能",'4.個人職能盤點'!$G$2:$G$1486,">0"),"-")) | L24: =IF(A24="","",IFERROR(AVERAGEIFS('4.個人職能盤點'!$I$2:$I$1486,'4.個人職能盤點'!$A$2:$A$1486,A24,'4.個人職能盤點'!$E$2:$E$1486,"專業職能",'4.個人職能盤點'!$G$2:$G$1486,">0"),"-")) | M24: =IF(H24="","",IF(H24>=0.9,"優秀",IF(H24>=0.7,"符合期待","需加強發展")))
A25: =IF('3.員工名單'!A25="","",'3.員工名單'!A25) | B25: =IF(A25="","",'3.員工名單'!B25) | C25: =IF(A25="","",'3.員工名單'!C25) | D25: =IF(A25="","",'3.員工名單'!D25) | E25: =IF(A25="","",COUNTIFS('4.個人職能盤點'!$A$2:$A$1486,A25,'4.個人職能盤點'!$K$2:$K$1486,"達標")+COUNTIFS('4.個人職能盤點'!$A$2:$A$1486,A25,'4.個人職能盤點'!$K$2:$K$1486,"超越")+COUNTIFS('4.個人職能盤點'!$A$2:$A$1486,A25,'4.個人職能盤點'!$K$2:$K$1486,"待發展")) | F25: =IF(A25="","",COUNTIFS('4.個人職能盤點'!$A$2:$A$1486,A25,'4.個人職能盤點'!$K$2:$K$1486,"達標")+COUNTIFS('4.個人職能盤點'!$A$2:$A$1486,A25,'4.個人職能盤點'!$K$2:$K$1486,"超越")) | G25: =IF(A25="","",COUNTIFS('4.個人職能盤點'!$A$2:$A$1486,A25,'4.個人職能盤點'!$K$2:$K$1486,"待發展")) | H25: =IF(OR(A25="",E25=0),"",F25/E25) | I25: =IF(OR(A25="",E25=0),"",IFERROR(AVERAGEIFS('4.個人職能盤點'!$J$2:$J$1486,'4.個人職能盤點'!$A$2:$A$1486,A25),"")) | J25: =IF(A25="","",IFERROR(AVERAGEIFS('4.個人職能盤點'!$I$2:$I$1486,'4.個人職能盤點'!$A$2:$A$1486,A25,'4.個人職能盤點'!$E$2:$E$1486,"核心職能",'4.個人職能盤點'!$G$2:$G$1486,">0"),"-")) | K25: =IF(A25="","",IFERROR(AVERAGEIFS('4.個人職能盤點'!$I$2:$I$1486,'4.個人職能盤點'!$A$2:$A$1486,A25,'4.個人職能盤點'!$E$2:$E$1486,"管理職能",'4.個人職能盤點'!$G$2:$G$1486,">0"),"-")) | L25: =IF(A25="","",IFERROR(AVERAGEIFS('4.個人職能盤點'!$I$2:$I$1486,'4.個人職能盤點'!$A$2:$A$1486,A25,'4.個人職能盤點'!$E$2:$E$1486,"專業職能",'4.個人職能盤點'!$G$2:$G$1486,">0"),"-")) | M25: =IF(H25="","",IF(H25>=0.9,"優秀",IF(H25>=0.7,"符合期待","需加強發展")))
A26: =IF('3.員工名單'!A26="","",'3.員工名單'!A26) | B26: =IF(A26="","",'3.員工名單'!B26) | C26: =IF(A26="","",'3.員工名單'!C26) | D26: =IF(A26="","",'3.員工名單'!D26) | E26: =IF(A26="","",COUNTIFS('4.個人職能盤點'!$A$2:$A$1486,A26,'4.個人職能盤點'!$K$2:$K$1486,"達標")+COUNTIFS('4.個人職能盤點'!$A$2:$A$1486,A26,'4.個人職能盤點'!$K$2:$K$1486,"超越")+COUNTIFS('4.個人職能盤點'!$A$2:$A$1486,A26,'4.個人職能盤點'!$K$2:$K$1486,"待發展")) | F26: =IF(A26="","",COUNTIFS('4.個人職能盤點'!$A$2:$A$1486,A26,'4.個人職能盤點'!$K$2:$K$1486,"達標")+COUNTIFS('4.個人職能盤點'!$A$2:$A$1486,A26,'4.個人職能盤點'!$K$2:$K$1486,"超越")) | G26: =IF(A26="","",COUNTIFS('4.個人職能盤點'!$A$2:$A$1486,A26,'4.個人職能盤點'!$K$2:$K$1486,"待發展")) | H26: =IF(OR(A26="",E26=0),"",F26/E26) | I26: =IF(OR(A26="",E26=0),"",IFERROR(AVERAGEIFS('4.個人職能盤點'!$J$2:$J$1486,'4.個人職能盤點'!$A$2:$A$1486,A26),"")) | J26: =IF(A26="","",IFERROR(AVERAGEIFS('4.個人職能盤點'!$I$2:$I$1486,'4.個人職能盤點'!$A$2:$A$1486,A26,'4.個人職能盤點'!$E$2:$E$1486,"核心職能",'4.個人職能盤點'!$G$2:$G$1486,">0"),"-")) | K26: =IF(A26="","",IFERROR(AVERAGEIFS('4.個人職能盤點'!$I$2:$I$1486,'4.個人職能盤點'!$A$2:$A$1486,A26,'4.個人職能盤點'!$E$2:$E$1486,"管理職能",'4.個人職能盤點'!$G$2:$G$1486,">0"),"-")) | L26: =IF(A26="","",IFERROR(AVERAGEIFS('4.個人職能盤點'!$I$2:$I$1486,'4.個人職能盤點'!$A$2:$A$1486,A26,'4.個人職能盤點'!$E$2:$E$1486,"專業職能",'4.個人職能盤點'!$G$2:$G$1486,">0"),"-")) | M26: =IF(H26="","",IF(H26>=0.9,"優秀",IF(H26>=0.7,"符合期待","需加強發展")))
A27: =IF('3.員工名單'!A27="","",'3.員工名單'!A27) | B27: =IF(A27="","",'3.員工名單'!B27) | C27: =IF(A27="","",'3.員工名單'!C27) | D27: =IF(A27="","",'3.員工名單'!D27) | E27: =IF(A27="","",COUNTIFS('4.個人職能盤點'!$A$2:$A$1486,A27,'4.個人職能盤點'!$K$2:$K$1486,"達標")+COUNTIFS('4.個人職能盤點'!$A$2:$A$1486,A27,'4.個人職能盤點'!$K$2:$K$1486,"超越")+COUNTIFS('4.個人職能盤點'!$A$2:$A$1486,A27,'4.個人職能盤點'!$K$2:$K$1486,"待發展")) | F27: =IF(A27="","",COUNTIFS('4.個人職能盤點'!$A$2:$A$1486,A27,'4.個人職能盤點'!$K$2:$K$1486,"達標")+COUNTIFS('4.個人職能盤點'!$A$2:$A$1486,A27,'4.個人職能盤點'!$K$2:$K$1486,"超越")) | G27: =IF(A27="","",COUNTIFS('4.個人職能盤點'!$A$2:$A$1486,A27,'4.個人職能盤點'!$K$2:$K$1486,"待發展")) | H27: =IF(OR(A27="",E27=0),"",F27/E27) | I27: =IF(OR(A27="",E27=0),"",IFERROR(AVERAGEIFS('4.個人職能盤點'!$J$2:$J$1486,'4.個人職能盤點'!$A$2:$A$1486,A27),"")) | J27: =IF(A27="","",IFERROR(AVERAGEIFS('4.個人職能盤點'!$I$2:$I$1486,'4.個人職能盤點'!$A$2:$A$1486,A27,'4.個人職能盤點'!$E$2:$E$1486,"核心職能",'4.個人職能盤點'!$G$2:$G$1486,">0"),"-")) | K27: =IF(A27="","",IFERROR(AVERAGEIFS('4.個人職能盤點'!$I$2:$I$1486,'4.個人職能盤點'!$A$2:$A$1486,A27,'4.個人職能盤點'!$E$2:$E$1486,"管理職能",'4.個人職能盤點'!$G$2:$G$1486,">0"),"-")) | L27: =IF(A27="","",IFERROR(AVERAGEIFS('4.個人職能盤點'!$I$2:$I$1486,'4.個人職能盤點'!$A$2:$A$1486,A27,'4.個人職能盤點'!$E$2:$E$1486,"專業職能",'4.個人職能盤點'!$G$2:$G$1486,">0"),"-")) | M27: =IF(H27="","",IF(H27>=0.9,"優秀",IF(H27>=0.7,"符合期待","需加強發展")))
A28: =IF('3.員工名單'!A28="","",'3.員工名單'!A28) | B28: =IF(A28="","",'3.員工名單'!B28) | C28: =IF(A28="","",'3.員工名單'!C28) | D28: =IF(A28="","",'3.員工名單'!D28) | E28: =IF(A28="","",COUNTIFS('4.個人職能盤點'!$A$2:$A$1486,A28,'4.個人職能盤點'!$K$2:$K$1486,"達標")+COUNTIFS('4.個人職能盤點'!$A$2:$A$1486,A28,'4.個人職能盤點'!$K$2:$K$1486,"超越")+COUNTIFS('4.個人職能盤點'!$A$2:$A$1486,A28,'4.個人職能盤點'!$K$2:$K$1486,"待發展")) | F28: =IF(A28="","",COUNTIFS('4.個人職能盤點'!$A$2:$A$1486,A28,'4.個人職能盤點'!$K$2:$K$1486,"達標")+COUNTIFS('4.個人職能盤點'!$A$2:$A$1486,A28,'4.個人職能盤點'!$K$2:$K$1486,"超越")) | G28: =IF(A28="","",COUNTIFS('4.個人職能盤點'!$A$2:$A$1486,A28,'4.個人職能盤點'!$K$2:$K$1486,"待發展")) | H28: =IF(OR(A28="",E28=0),"",F28/E28) | I28: =IF(OR(A28="",E28=0),"",IFERROR(AVERAGEIFS('4.個人職能盤點'!$J$2:$J$1486,'4.個人職能盤點'!$A$2:$A$1486,A28),"")) | J28: =IF(A28="","",IFERROR(AVERAGEIFS('4.個人職能盤點'!$I$2:$I$1486,'4.個人職能盤點'!$A$2:$A$1486,A28,'4.個人職能盤點'!$E$2:$E$1486,"核心職能",'4.個人職能盤點'!$G$2:$G$1486,">0"),"-")) | K28: =IF(A28="","",IFERROR(AVERAGEIFS('4.個人職能盤點'!$I$2:$I$1486,'4.個人職能盤點'!$A$2:$A$1486,A28,'4.個人職能盤點'!$E$2:$E$1486,"管理職能",'4.個人職能盤點'!$G$2:$G$1486,">0"),"-")) | L28: =IF(A28="","",IFERROR(AVERAGEIFS('4.個人職能盤點'!$I$2:$I$1486,'4.個人職能盤點'!$A$2:$A$1486,A28,'4.個人職能盤點'!$E$2:$E$1486,"專業職能",'4.個人職能盤點'!$G$2:$G$1486,">0"),"-")) | M28: =IF(H28="","",IF(H28>=0.9,"優秀",IF(H28>=0.7,"符合期待","需加強發展")))
A29: =IF('3.員工名單'!A29="","",'3.員工名單'!A29) | B29: =IF(A29="","",'3.員工名單'!B29) | C29: =IF(A29="","",'3.員工名單'!C29) | D29: =IF(A29="","",'3.員工名單'!D29) | E29: =IF(A29="","",COUNTIFS('4.個人職能盤點'!$A$2:$A$1486,A29,'4.個人職能盤點'!$K$2:$K$1486,"達標")+COUNTIFS('4.個人職能盤點'!$A$2:$A$1486,A29,'4.個人職能盤點'!$K$2:$K$1486,"超越")+COUNTIFS('4.個人職能盤點'!$A$2:$A$1486,A29,'4.個人職能盤點'!$K$2:$K$1486,"待發展")) | F29: =IF(A29="","",COUNTIFS('4.個人職能盤點'!$A$2:$A$1486,A29,'4.個人職能盤點'!$K$2:$K$1486,"達標")+COUNTIFS('4.個人職能盤點'!$A$2:$A$1486,A29,'4.個人職能盤點'!$K$2:$K$1486,"超越")) | G29: =IF(A29="","",COUNTIFS('4.個人職能盤點'!$A$2:$A$1486,A29,'4.個人職能盤點'!$K$2:$K$1486,"待發展")) | H29: =IF(OR(A29="",E29=0),"",F29/E29) | I29: =IF(OR(A29="",E29=0),"",IFERROR(AVERAGEIFS('4.個人職能盤點'!$J$2:$J$1486,'4.個人職能盤點'!$A$2:$A$1486,A29),"")) | J29: =IF(A29="","",IFERROR(AVERAGEIFS('4.個人職能盤點'!$I$2:$I$1486,'4.個人職能盤點'!$A$2:$A$1486,A29,'4.個人職能盤點'!$E$2:$E$1486,"核心職能",'4.個人職能盤點'!$G$2:$G$1486,">0"),"-")) | K29: =IF(A29="","",IFERROR(AVERAGEIFS('4.個人職能盤點'!$I$2:$I$1486,'4.個人職能盤點'!$A$2:$A$1486,A29,'4.個人職能盤點'!$E$2:$E$1486,"管理職能",'4.個人職能盤點'!$G$2:$G$1486,">0"),"-")) | L29: =IF(A29="","",IFERROR(AVERAGEIFS('4.個人職能盤點'!$I$2:$I$1486,'4.個人職能盤點'!$A$2:$A$1486,A29,'4.個人職能盤點'!$E$2:$E$1486,"專業職能",'4.個人職能盤點'!$G$2:$G$1486,">0"),"-")) | M29: =IF(H29="","",IF(H29>=0.9,"優秀",IF(H29>=0.7,"符合期待","需加強發展")))
A30: =IF('3.員工名單'!A30="","",'3.員工名單'!A30) | B30: =IF(A30="","",'3.員工名單'!B30) | C30: =IF(A30="","",'3.員工名單'!C30) | D30: =IF(A30="","",'3.員工名單'!D30) | E30: =IF(A30="","",COUNTIFS('4.個人職能盤點'!$A$2:$A$1486,A30,'4.個人職能盤點'!$K$2:$K$1486,"達標")+COUNTIFS('4.個人職能盤點'!$A$2:$A$1486,A30,'4.個人職能盤點'!$K$2:$K$1486,"超越")+COUNTIFS('4.個人職能盤點'!$A$2:$A$1486,A30,'4.個人職能盤點'!$K$2:$K$1486,"待發展")) | F30: =IF(A30="","",COUNTIFS('4.個人職能盤點'!$A$2:$A$1486,A30,'4.個人職能盤點'!$K$2:$K$1486,"達標")+COUNTIFS('4.個人職能盤點'!$A$2:$A$1486,A30,'4.個人職能盤點'!$K$2:$K$1486,"超越")) | G30: =IF(A30="","",COUNTIFS('4.個人職能盤點'!$A$2:$A$1486,A30,'4.個人職能盤點'!$K$2:$K$1486,"待發展")) | H30: =IF(OR(A30="",E30=0),"",F30/E30) | I30: =IF(OR(A30="",E30=0),"",IFERROR(AVERAGEIFS('4.個人職能盤點'!$J$2:$J$1486,'4.個人職能盤點'!$A$2:$A$1486,A30),"")) | J30: =IF(A30="","",IFERROR(AVERAGEIFS('4.個人職能盤點'!$I$2:$I$1486,'4.個人職能盤點'!$A$2:$A$1486,A30,'4.個人職能盤點'!$E$2:$E$1486,"核心職能",'4.個人職能盤點'!$G$2:$G$1486,">0"),"-")) | K30: =IF(A30="","",IFERROR(AVERAGEIFS('4.個人職能盤點'!$I$2:$I$1486,'4.個人職能盤點'!$A$2:$A$1486,A30,'4.個人職能盤點'!$E$2:$E$1486,"管理職能",'4.個人職能盤點'!$G$2:$G$1486,">0"),"-")) | L30: =IF(A30="","",IFERROR(AVERAGEIFS('4.個人職能盤點'!$I$2:$I$1486,'4.個人職能盤點'!$A$2:$A$1486,A30,'4.個人職能盤點'!$E$2:$E$1486,"專業職能",'4.個人職能盤點'!$G$2:$G$1486,">0"),"-")) | M30: =IF(H30="","",IF(H30>=0.9,"優秀",IF(H30>=0.7,"符合期待","需加強發展")))
A31: =IF('3.員工名單'!A31="","",'3.員工名單'!A31) | B31: =IF(A31="","",'3.員工名單'!B31) | C31: =IF(A31="","",'3.員工名單'!C31) | D31: =IF(A31="","",'3.員工名單'!D31) | E31: =IF(A31="","",COUNTIFS('4.個人職能盤點'!$A$2:$A$1486,A31,'4.個人職能盤點'!$K$2:$K$1486,"達標")+COUNTIFS('4.個人職能盤點'!$A$2:$A$1486,A31,'4.個人職能盤點'!$K$2:$K$1486,"超越")+COUNTIFS('4.個人職能盤點'!$A$2:$A$1486,A31,'4.個人職能盤點'!$K$2:$K$1486,"待發展")) | F31: =IF(A31="","",COUNTIFS('4.個人職能盤點'!$A$2:$A$1486,A31,'4.個人職能盤點'!$K$2:$K$1486,"達標")+COUNTIFS('4.個人職能盤點'!$A$2:$A$1486,A31,'4.個人職能盤點'!$K$2:$K$1486,"超越")) | G31: =IF(A31="","",COUNTIFS('4.個人職能盤點'!$A$2:$A$1486,A31,'4.個人職能盤點'!$K$2:$K$1486,"待發展")) | H31: =IF(OR(A31="",E31=0),"",F31/E31) | I31: =IF(OR(A31="",E31=0),"",IFERROR(AVERAGEIFS('4.個人職能盤點'!$J$2:$J$1486,'4.個人職能盤點'!$A$2:$A$1486,A31),"")) | J31: =IF(A31="","",IFERROR(AVERAGEIFS('4.個人職能盤點'!$I$2:$I$1486,'4.個人職能盤點'!$A$2:$A$1486,A31,'4.個人職能盤點'!$E$2:$E$1486,"核心職能",'4.個人職能盤點'!$G$2:$G$1486,">0"),"-")) | K31: =IF(A31="","",IFERROR(AVERAGEIFS('4.個人職能盤點'!$I$2:$I$1486,'4.個人職能盤點'!$A$2:$A$1486,A31,'4.個人職能盤點'!$E$2:$E$1486,"管理職能",'4.個人職能盤點'!$G$2:$G$1486,">0"),"-")) | L31: =IF(A31="","",IFERROR(AVERAGEIFS('4.個人職能盤點'!$I$2:$I$1486,'4.個人職能盤點'!$A$2:$A$1486,A31,'4.個人職能盤點'!$E$2:$E$1486,"專業職能",'4.個人職能盤點'!$G$2:$G$1486,">0"),"-")) | M31: =IF(H31="","",IF(H31>=0.9,"優秀",IF(H31>=0.7,"符合期待","需加強發展")))
A32: =IF('3.員工名單'!A32="","",'3.員工名單'!A32) | B32: =IF(A32="","",'3.員工名單'!B32) | C32: =IF(A32="","",'3.員工名單'!C32) | D32: =IF(A32="","",'3.員工名單'!D32) | E32: =IF(A32="","",COUNTIFS('4.個人職能盤點'!$A$2:$A$1486,A32,'4.個人職能盤點'!$K$2:$K$1486,"達標")+COUNTIFS('4.個人職能盤點'!$A$2:$A$1486,A32,'4.個人職能盤點'!$K$2:$K$1486,"超越")+COUNTIFS('4.個人職能盤點'!$A$2:$A$1486,A32,'4.個人職能盤點'!$K$2:$K$1486,"待發展")) | F32: =IF(A32="","",COUNTIFS('4.個人職能盤點'!$A$2:$A$1486,A32,'4.個人職能盤點'!$K$2:$K$1486,"達標")+COUNTIFS('4.個人職能盤點'!$A$2:$A$1486,A32,'4.個人職能盤點'!$K$2:$K$1486,"超越")) | G32: =IF(A32="","",COUNTIFS('4.個人職能盤點'!$A$2:$A$1486,A32,'4.個人職能盤點'!$K$2:$K$1486,"待發展")) | H32: =IF(OR(A32="",E32=0),"",F32/E32) | I32: =IF(OR(A32="",E32=0),"",IFERROR(AVERAGEIFS('4.個人職能盤點'!$J$2:$J$1486,'4.個人職能盤點'!$A$2:$A$1486,A32),"")) | J32: =IF(A32="","",IFERROR(AVERAGEIFS('4.個人職能盤點'!$I$2:$I$1486,'4.個人職能盤點'!$A$2:$A$1486,A32,'4.個人職能盤點'!$E$2:$E$1486,"核心職能",'4.個人職能盤點'!$G$2:$G$1486,">0"),"-")) | K32: =IF(A32="","",IFERROR(AVERAGEIFS('4.個人職能盤點'!$I$2:$I$1486,'4.個人職能盤點'!$A$2:$A$1486,A32,'4.個人職能盤點'!$E$2:$E$1486,"管理職能",'4.個人職能盤點'!$G$2:$G$1486,">0"),"-")) | L32: =IF(A32="","",IFERROR(AVERAGEIFS('4.個人職能盤點'!$I$2:$I$1486,'4.個人職能盤點'!$A$2:$A$1486,A32,'4.個人職能盤點'!$E$2:$E$1486,"專業職能",'4.個人職能盤點'!$G$2:$G$1486,">0"),"-")) | M32: =IF(H32="","",IF(H32>=0.9,"優秀",IF(H32>=0.7,"符合期待","需加強發展")))
A33: =IF('3.員工名單'!A33="","",'3.員工名單'!A33) | B33: =IF(A33="","",'3.員工名單'!B33) | C33: =IF(A33="","",'3.員工名單'!C33) | D33: =IF(A33="","",'3.員工名單'!D33) | E33: =IF(A33="","",COUNTIFS('4.個人職能盤點'!$A$2:$A$1486,A33,'4.個人職能盤點'!$K$2:$K$1486,"達標")+COUNTIFS('4.個人職能盤點'!$A$2:$A$1486,A33,'4.個人職能盤點'!$K$2:$K$1486,"超越")+COUNTIFS('4.個人職能盤點'!$A$2:$A$1486,A33,'4.個人職能盤點'!$K$2:$K$1486,"待發展")) | F33: =IF(A33="","",COUNTIFS('4.個人職能盤點'!$A$2:$A$1486,A33,'4.個人職能盤點'!$K$2:$K$1486,"達標")+COUNTIFS('4.個人職能盤點'!$A$2:$A$1486,A33,'4.個人職能盤點'!$K$2:$K$1486,"超越")) | G33: =IF(A33="","",COUNTIFS('4.個人職能盤點'!$A$2:$A$1486,A33,'4.個人職能盤點'!$K$2:$K$1486,"待發展")) | H33: =IF(OR(A33="",E33=0),"",F33/E33) | I33: =IF(OR(A33="",E33=0),"",IFERROR(AVERAGEIFS('4.個人職能盤點'!$J$2:$J$1486,'4.個人職能盤點'!$A$2:$A$1486,A33),"")) | J33: =IF(A33="","",IFERROR(AVERAGEIFS('4.個人職能盤點'!$I$2:$I$1486,'4.個人職能盤點'!$A$2:$A$1486,A33,'4.個人職能盤點'!$E$2:$E$1486,"核心職能",'4.個人職能盤點'!$G$2:$G$1486,">0"),"-")) | K33: =IF(A33="","",IFERROR(AVERAGEIFS('4.個人職能盤點'!$I$2:$I$1486,'4.個人職能盤點'!$A$2:$A$1486,A33,'4.個人職能盤點'!$E$2:$E$1486,"管理職能",'4.個人職能盤點'!$G$2:$G$1486,">0"),"-")) | L33: =IF(A33="","",IFERROR(AVERAGEIFS('4.個人職能盤點'!$I$2:$I$1486,'4.個人職能盤點'!$A$2:$A$1486,A33,'4.個人職能盤點'!$E$2:$E$1486,"專業職能",'4.個人職能盤點'!$G$2:$G$1486,">0"),"-")) | M33: =IF(H33="","",IF(H33>=0.9,"優秀",IF(H33>=0.7,"符合期待","需加強發展")))
A34: =IF('3.員工名單'!A34="","",'3.員工名單'!A34) | B34: =IF(A34="","",'3.員工名單'!B34) | C34: =IF(A34="","",'3.員工名單'!C34) | D34: =IF(A34="","",'3.員工名單'!D34) | E34: =IF(A34="","",COUNTIFS('4.個人職能盤點'!$A$2:$A$1486,A34,'4.個人職能盤點'!$K$2:$K$1486,"達標")+COUNTIFS('4.個人職能盤點'!$A$2:$A$1486,A34,'4.個人職能盤點'!$K$2:$K$1486,"超越")+COUNTIFS('4.個人職能盤點'!$A$2:$A$1486,A34,'4.個人職能盤點'!$K$2:$K$1486,"待發展")) | F34: =IF(A34="","",COUNTIFS('4.個人職能盤點'!$A$2:$A$1486,A34,'4.個人職能盤點'!$K$2:$K$1486,"達標")+COUNTIFS('4.個人職能盤點'!$A$2:$A$1486,A34,'4.個人職能盤點'!$K$2:$K$1486,"超越")) | G34: =IF(A34="","",COUNTIFS('4.個人職能盤點'!$A$2:$A$1486,A34,'4.個人職能盤點'!$K$2:$K$1486,"待發展")) | H34: =IF(OR(A34="",E34=0),"",F34/E34) | I34: =IF(OR(A34="",E34=0),"",IFERROR(AVERAGEIFS('4.個人職能盤點'!$J$2:$J$1486,'4.個人職能盤點'!$A$2:$A$1486,A34),"")) | J34: =IF(A34="","",IFERROR(AVERAGEIFS('4.個人職能盤點'!$I$2:$I$1486,'4.個人職能盤點'!$A$2:$A$1486,A34,'4.個人職能盤點'!$E$2:$E$1486,"核心職能",'4.個人職能盤點'!$G$2:$G$1486,">0"),"-")) | K34: =IF(A34="","",IFERROR(AVERAGEIFS('4.個人職能盤點'!$I$2:$I$1486,'4.個人職能盤點'!$A$2:$A$1486,A34,'4.個人職能盤點'!$E$2:$E$1486,"管理職能",'4.個人職能盤點'!$G$2:$G$1486,">0"),"-")) | L34: =IF(A34="","",IFERROR(AVERAGEIFS('4.個人職能盤點'!$I$2:$I$1486,'4.個人職能盤點'!$A$2:$A$1486,A34,'4.個人職能盤點'!$E$2:$E$1486,"專業職能",'4.個人職能盤點'!$G$2:$G$1486,">0"),"-")) | M34: =IF(H34="","",IF(H34>=0.9,"優秀",IF(H34>=0.7,"符合期待","需加強發展")))
A35: =IF('3.員工名單'!A35="","",'3.員工名單'!A35) | B35: =IF(A35="","",'3.員工名單'!B35) | C35: =IF(A35="","",'3.員工名單'!C35) | D35: =IF(A35="","",'3.員工名單'!D35) | E35: =IF(A35="","",COUNTIFS('4.個人職能盤點'!$A$2:$A$1486,A35,'4.個人職能盤點'!$K$2:$K$1486,"達標")+COUNTIFS('4.個人職能盤點'!$A$2:$A$1486,A35,'4.個人職能盤點'!$K$2:$K$1486,"超越")+COUNTIFS('4.個人職能盤點'!$A$2:$A$1486,A35,'4.個人職能盤點'!$K$2:$K$1486,"待發展")) | F35: =IF(A35="","",COUNTIFS('4.個人職能盤點'!$A$2:$A$1486,A35,'4.個人職能盤點'!$K$2:$K$1486,"達標")+COUNTIFS('4.個人職能盤點'!$A$2:$A$1486,A35,'4.個人職能盤點'!$K$2:$K$1486,"超越")) | G35: =IF(A35="","",COUNTIFS('4.個人職能盤點'!$A$2:$A$1486,A35,'4.個人職能盤點'!$K$2:$K$1486,"待發展")) | H35: =IF(OR(A35="",E35=0),"",F35/E35) | I35: =IF(OR(A35="",E35=0),"",IFERROR(AVERAGEIFS('4.個人職能盤點'!$J$2:$J$1486,'4.個人職能盤點'!$A$2:$A$1486,A35),"")) | J35: =IF(A35="","",IFERROR(AVERAGEIFS('4.個人職能盤點'!$I$2:$I$1486,'4.個人職能盤點'!$A$2:$A$1486,A35,'4.個人職能盤點'!$E$2:$E$1486,"核心職能",'4.個人職能盤點'!$G$2:$G$1486,">0"),"-")) | K35: =IF(A35="","",IFERROR(AVERAGEIFS('4.個人職能盤點'!$I$2:$I$1486,'4.個人職能盤點'!$A$2:$A$1486,A35,'4.個人職能盤點'!$E$2:$E$1486,"管理職能",'4.個人職能盤點'!$G$2:$G$1486,">0"),"-")) | L35: =IF(A35="","",IFERROR(AVERAGEIFS('4.個人職能盤點'!$I$2:$I$1486,'4.個人職能盤點'!$A$2:$A$1486,A35,'4.個人職能盤點'!$E$2:$E$1486,"專業職能",'4.個人職能盤點'!$G$2:$G$1486,">0"),"-")) | M35: =IF(H35="","",IF(H35>=0.9,"優秀",IF(H35>=0.7,"符合期待","需加強發展")))
A36: =IF('3.員工名單'!A36="","",'3.員工名單'!A36) | B36: =IF(A36="","",'3.員工名單'!B36) | C36: =IF(A36="","",'3.員工名單'!C36) | D36: =IF(A36="","",'3.員工名單'!D36) | E36: =IF(A36="","",COUNTIFS('4.個人職能盤點'!$A$2:$A$1486,A36,'4.個人職能盤點'!$K$2:$K$1486,"達標")+COUNTIFS('4.個人職能盤點'!$A$2:$A$1486,A36,'4.個人職能盤點'!$K$2:$K$1486,"超越")+COUNTIFS('4.個人職能盤點'!$A$2:$A$1486,A36,'4.個人職能盤點'!$K$2:$K$1486,"待發展")) | F36: =IF(A36="","",COUNTIFS('4.個人職能盤點'!$A$2:$A$1486,A36,'4.個人職能盤點'!$K$2:$K$1486,"達標")+COUNTIFS('4.個人職能盤點'!$A$2:$A$1486,A36,'4.個人職能盤點'!$K$2:$K$1486,"超越")) | G36: =IF(A36="","",COUNTIFS('4.個人職能盤點'!$A$2:$A$1486,A36,'4.個人職能盤點'!$K$2:$K$1486,"待發展")) | H36: =IF(OR(A36="",E36=0),"",F36/E36) | I36: =IF(OR(A36="",E36=0),"",IFERROR(AVERAGEIFS('4.個人職能盤點'!$J$2:$J$1486,'4.個人職能盤點'!$A$2:$A$1486,A36),"")) | J36: =IF(A36="","",IFERROR(AVERAGEIFS('4.個人職能盤點'!$I$2:$I$1486,'4.個人職能盤點'!$A$2:$A$1486,A36,'4.個人職能盤點'!$E$2:$E$1486,"核心職能",'4.個人職能盤點'!$G$2:$G$1486,">0"),"-")) | K36: =IF(A36="","",IFERROR(AVERAGEIFS('4.個人職能盤點'!$I$2:$I$1486,'4.個人職能盤點'!$A$2:$A$1486,A36,'4.個人職能盤點'!$E$2:$E$1486,"管理職能",'4.個人職能盤點'!$G$2:$G$1486,">0"),"-")) | L36: =IF(A36="","",IFERROR(AVERAGEIFS('4.個人職能盤點'!$I$2:$I$1486,'4.個人職能盤點'!$A$2:$A$1486,A36,'4.個人職能盤點'!$E$2:$E$1486,"專業職能",'4.個人職能盤點'!$G$2:$G$1486,">0"),"-")) | M36: =IF(H36="","",IF(H36>=0.9,"優秀",IF(H36>=0.7,"符合期待","需加強發展")))
